Workbook

Sheet 使い方
A1: BOOTH売上CSVを貼るだけ 月次集計シート【無料版】
A2: by 無駄尾なくす ― めんどくさいので、なくします。
A4: ■ できること
A5: BOOTHの「売上管理CSV」を貼り付けるだけで、月ごとの 売上（小計）・送料・BOOTH手数料・受取金額 を自動で集計します。
A7: ■ 使い方（3ステップ）
A8: 1. BOOTHのショップ管理 →「売上管理」から、集計したい月の売上管理CSVをダウンロードする（1回につき最大31日分）。
A9: 2. CSVを開いて全体をコピーし、「貼り付け」シートのA1セルに貼る。2か月目以降は、前のデータの下の空いている行に、見出し行ごと貼ってOK。
A10: 3. 「月次集計」シートの年（B3セル）を選ぶ。月ごとの数字が自動で出ます。
A12: ■ うまく集計されないとき
A13: 「月次集計」シートの「読み取った列」に「見つかりません」と出ている場合、CSVの見出し名が想定と違います。お手数ですが購入ページのメッセージ機能などでお知らせください。
A14: 日付が文字列の形（例：2026/1/5）の場合も読み取りますが、うまくいかない場合はお知らせください。
A15: 貼り付けできるのは3,000行までです。
... A28: 欲しい方は、BOOTHでショップをフォローしておいてください。公開したらお知らせします。

Sheet 月次集計
A1: BOOTH 月次集計
A3: 集計する年 | B3: 2026
A5: 月 | B5: 明細の行数 | C5: 売上（小計） | D5: 送料 | E5: BOOTH手数料 | F5: 受取金額
A6: 1月 | B6: =COUNTIFS(計算!$G$3:$G$3002,$B$3,計算!$H$3:$H$3002,1) | C6: =SUMIFS(計算!$C$3:$C$3002,計算!$G$3:$G$3002,$B$3,計算!$H$3:$H$3002,1) | D6: =SUMIFS(計算!$D$3:$D$3002,計算!$G$3:$G$3002,$B$3,計算!$H$3:$H$3002,1) | E6: =SUMIFS(計算!$E$3:$E$3002,計算!$G$3:$G$3002,$B$3,計算!$H$3:$H$3002,1) | F6: =SUMIFS(計算!$F$3:$F$3002,計算!$G$3:$G$3002,$B$3,計算!$H$3:$H$3002,1)
A7: 2月 | B7: =COUNTIFS(計算!$G$3:$G$3002,$B$3,計算!$H$3:$H$3002,2) | C7: =SUMIFS(計算!$C$3:$C$3002,計算!$G$3:$G$3002,$B$3,計算!$H$3:$H$3002,2) | D7: =SUMIFS(計算!$D$3:$D$3002,計算!$G$3:$G$3002,$B$3,計算!$H$3:$H$3002,2) | E7: =SUMIFS(計算!$E$3:$E$3002,計算!$G$3:$G$3002,$B$3,計算!$H$3:$H$3002,2) | F7: =SUMIFS(計算!$F$3:$F$3002,計算!$G$3:$G$3002,$B$3,計算!$H$3:$H$3002,2)
A8: 3月 | B8: =COUNTIFS(計算!$G$3:$G$3002,$B$3,計算!$H$3:$H$3002,3) | C8: =SUMIFS(計算!$C$3:$C$3002,計算!$G$3:$G$3002,$B$3,計算!$H$3:$H$3002,3) | D8: =SUMIFS(計算!$D$3:$D$3002,計算!$G$3:$G$3002,$B$3,計算!$H$3:$H$3002,3) | E8: =SUMIFS(計算!$E$3:$E$3002,計算!$G$3:$G$3002,$B$3,計算!$H$3:$H$3002,3) | F8: =SUMIFS(計算!$F$3:$F$3002,計算!$G$3:$G$3002,$B$3,計算!$H$3:$H$3002,3)
A9: 4月 | B9: =COUNTIFS(計算!$G$3:$G$3002,$B$3,計算!$H$3:$H$3002,4) | C9: =SUMIFS(計算!$C$3:$C$3002,計算!$G$3:$G$3002,$B$3,計算!$H$3:$H$3002,4) | D9: =SUMIFS(計算!$D$3:$D$3002,計算!$G$3:$G$3002,$B$3,計算!$H$3:$H$3002,4) | E9: =SUMIFS(計算!$E$3:$E$3002,計算!$G$3:$G$3002,$B$3,計算!$H$3:$H$3002,4) | F9: =SUMIFS(計算!$F$3:$F$3002,計算!$G$3:$G$3002,$B$3,計算!$H$3:$H$3002,4)
A10: 5月 | B10: =COUNTIFS(計算!$G$3:$G$3002,$B$3,計算!$H$3:$H$3002,5) | C10: =SUMIFS(計算!$C$3:$C$3002,計算!$G$3:$G$3002,$B$3,計算!$H$3:$H$3002,5) | D10: =SUMIFS(計算!$D$3:$D$3002,計算!$G$3:$G$3002,$B$3,計算!$H$3:$H$3002,5) | E10: =SUMIFS(計算!$E$3:$E$3002,計算!$G$3:$G$3002,$B$3,計算!$H$3:$H$3002,5) | F10: =SUMIFS(計算!$F$3:$F$3002,計算!$G$3:$G$3002,$B$3,計算!$H$3:$H$3002,5)
A11: 6月 | B11: =COUNTIFS(計算!$G$3:$G$3002,$B$3,計算!$H$3:$H$3002,6) | C11: =SUMIFS(計算!$C$3:$C$3002,計算!$G$3:$G$3002,$B$3,計算!$H$3:$H$3002,6) | D11: =SUMIFS(計算!$D$3:$D$3002,計算!$G$3:$G$3002,$B$3,計算!$H$3:$H$3002,6) | E11: =SUMIFS(計算!$E$3:$E$3002,計算!$G$3:$G$3002,$B$3,計算!$H$3:$H$3002,6) | F11: =SUMIFS(計算!$F$3:$F$3002,計算!$G$3:$G$3002,$B$3,計算!$H$3:$H$3002,6)
A12: 7月 | B12: =COUNTIFS(計算!$G$3:$G$3002,$B$3,計算!$H$3:$H$3002,7) | C12: =SUMIFS(計算!$C$3:$C$3002,計算!$G$3:$G$3002,$B$3,計算!$H$3:$H$3002,7) | D12: =SUMIFS(計算!$D$3:$D$3002,計算!$G$3:$G$3002,$B$3,計算!$H$3:$H$3002,7) | E12: =SUMIFS(計算!$E$3:$E$3002,計算!$G$3:$G$3002,$B$3,計算!$H$3:$H$3002,7) | F12: =SUMIFS(計算!$F$3:$F$3002,計算!$G$3:$G$3002,$B$3,計算!$H$3:$H$3002,7)
A13: 8月 | B13: =COUNTIFS(計算!$G$3:$G$3002,$B$3,計算!$H$3:$H$3002,8) | C13: =SUMIFS(計算!$C$3:$C$3002,計算!$G$3:$G$3002,$B$3,計算!$H$3:$H$3002,8) | D13: =SUMIFS(計算!$D$3:$D$3002,計算!$G$3:$G$3002,$B$3,計算!$H$3:$H$3002,8) | E13: =SUMIFS(計算!$E$3:$E$3002,計算!$G$3:$G$3002,$B$3,計算!$H$3:$H$3002,8) | F13: =SUMIFS(計算!$F$3:$F$3002,計算!$G$3:$G$3002,$B$3,計算!$H$3:$H$3002,8)
A14: 9月 | B14: =COUNTIFS(計算!$G$3:$G$3002,$B$3,計算!$H$3:$H$3002,9) | C14: =SUMIFS(計算!$C$3:$C$3002,計算!$G$3:$G$3002,$B$3,計算!$H$3:$H$3002,9) | D14: =SUMIFS(計算!$D$3:$D$3002,計算!$G$3:$G$3002,$B$3,計算!$H$3:$H$3002,9) | E14: =SUMIFS(計算!$E$3:$E$3002,計算!$G$3:$G$3002,$B$3,計算!$H$3:$H$3002,9) | F14: =SUMIFS(計算!$F$3:$F$3002,計算!$G$3:$G$3002,$B$3,計算!$H$3:$H$3002,9)
A15: 10月 | B15: =COUNTIFS(計算!$G$3:$G$3002,$B$3,計算!$H$3:$H$3002,10) | C15: =SUMIFS(計算!$C$3:$C$3002,計算!$G$3:$G$3002,$B$3,計算!$H$3:$H$3002,10) | D15: =SUMIFS(計算!$D$3:$D$3002,計算!$G$3:$G$3002,$B$3,計算!$H$3:$H$3002,10) | E15: =SUMIFS(計算!$E$3:$E$3002,計算!$G$3:$G$3002,$B$3,計算!$H$3:$H$3002,10) | F15: =SUMIFS(計算!$F$3:$F$3002,計算!$G$3:$G$3002,$B$3,計算!$H$3:$H$3002,10)
A16: 11月 | B16: =COUNTIFS(計算!$G$3:$G$3002,$B$3,計算!$H$3:$H$3002,11) | C16: =SUMIFS(計算!$C$3:$C$3002,計算!$G$3:$G$3002,$B$3,計算!$H$3:$H$3002,11) | D16: =SUMIFS(計算!$D$3:$D$3002,計算!$G$3:$G$3002,$B$3,計算!$H$3:$H$3002,11) | E16: =SUMIFS(計算!$E$3:$E$3002,計算!$G$3:$G$3002,$B$3,計算!$H$3:$H$3002,11) | F16: =SUMIFS(計算!$F$3:$F$3002,計算!$G$3:$G$3002,$B$3,計算!$H$3:$H$3002,11)
A17: 12月 | B17: =COUNTIFS(計算!$G$3:$G$3002,$B$3,計算!$H$3:$H$3002,12) | C17: =SUMIFS(計算!$C$3:$C$3002,計算!$G$3:$G$3002,$B$3,計算!$H$3:$H$3002,12) | D17: =SUMIFS(計算!$D$3:$D$3002,計算!$G$3:$G$3002,$B$3,計算!$H$3:$H$3002,12) | E17: =SUMIFS(計算!$E$3:$E$3002,計算!$G$3:$G$3002,$B$3,計算!$H$3:$H$3002,12) | F17: =SUMIFS(計算!$F$3:$F$3002,計算!$G$3:$G$3002,$B$3,計算!$H$3:$H$3002,12)
A18: 年間合計 | B18: =SUM(B6:B17) | C18: =SUM(C6:C17) | D18: =SUM(D6:D17) | E18: =SUM(E6:E17) | F18: =SUM(F6:F17)
A20: 手数料の割合（手数料÷売上） | C20: =IF(C18=0,"",E18/C18)
A22: 読み取った列（「見つかりません」がないか確認）
A23: 日時 | B23: =IF(計算!B1=0,"見つかりません",INDEX(貼り付け!$A$1:$BZ$1,1,計算!B1))
A24: 小計 | B24: =IF(計算!C1=0,"見つかりません",INDEX(貼り付け!$A$1:$BZ$1,1,計算!C1))
A25: 送料 | B25: =IF(計算!D1=0,"見つかりません",INDEX(貼り付け!$A$1:$BZ$1,1,計算!D1))
A26: 手数料 | B26: =IF(計算!E1=0,"見つかりません",INDEX(貼り付け!$A$1:$BZ$1,1,計算!E1))
A27: 受取金額 | B27: =IF(計算!F1=0,"見つかりません",INDEX(貼り付け!$A$1:$BZ$1,1,計算!F1))
A29: ※ 確定申告の内容の正しさは保証しません。BOOTHの管理画面・入金記録と照らし合わせて確認してください。
A30: 有料版（準備中）：note・FANBOX・Skebなどの売上の年間まとめ、経費シート、商品別ランキング

Sheet 貼り付け

Sheet 計算
A1: 列番号 | B1: =IFERROR(MATCH("*注文日時*",貼り付け!$A$1:$BZ$1,0),0) | C1: =IFERROR(MATCH("*小計*",貼り付け!$A$1:$BZ$1,0),0) | D1: =IFERROR(MATCH("*送料*",貼り付け!$A$1:$BZ$1,0),0) | E1: =IFERROR(MATCH("*手数料*",貼り付け!$A$1:$BZ$1,0),0) | F1: =IFERROR(MATCH("*受取*",貼り付け!$A$1:$BZ$1,0),0)
B2: 日時 | C2: 小計 | D2: 送料 | E2: 手数料 | F2: 受取金額 | G2: 年 | H2: 月
B3: =IFERROR(IF($B$1=0,"",IF(INDEX(貼り付け!$A$1:$BZ$3001,2,$B$1)="","",IF(ISNUMBER(INDEX(貼り付け!$A$1:$BZ$3001,2,$B$1)),INT(INDEX(貼り付け!$A$1:$BZ$3001,2,$B$1)),DATE(VALUE(LEFT(I3,FIND("-",I3)-1)),VALUE(LEFT(J3,FIND("-",J3)-1)),VALUE(MID(J3,FIND("-",J3)+1,99)))))),"") | C3: =IF($C$1=0,0,IFERROR(VALUE(SUBSTITUTE(SUBSTITUTE(SUBSTITUTE(INDEX(貼り付け!$A$1:$BZ$3001,2,$C$1)&"",",",""),"¥",""),"￥","")),0)) | D3: =IF($D$1=0,0,IFERROR(VALUE(SUBSTITUTE(SUBSTITUTE(SUBSTITUTE(INDEX(貼り付け!$A$1:$BZ$3001,2,$D$1)&"",",",""),"¥",""),"￥","")),0)) | E3: =IF($E$1=0,0,IFERROR(VALUE(SUBSTITUTE(SUBSTITUTE(SUBSTITUTE(INDEX(貼り付け!$A$1:$BZ$3001,2,$E$1)&"",",",""),"¥",""),"￥","")),0)) | F3: =IF($F$1=0,0,IFERROR(VALUE(SUBSTITUTE(SUBSTITUTE(SUBSTITUTE(INDEX(貼り付け!$A$1:$BZ$3001,2,$F$1)&"",",",""),"¥",""),"￥","")),0)) | G3: =IF(ISNUMBER(B3),YEAR(B3),"") | H3: =IF(ISNUMBER(B3),MONTH(B3),"") | I3: =IFERROR(IF($B$1=0,"",IF(ISNUMBER(INDEX(貼り付け!$A$1:$BZ$3001,2,$B$1)),"",SUBSTITUTE(SUBSTITUTE(SUBSTITUTE(SUBSTITUTE(TRIM(LEFT(INDEX(貼り付け!$A$1:$BZ$3001,2,$B$1)&"",FIND(" ",TRIM(INDEX(貼り付け!$A$1:$BZ$3001,2,$B$1)&"")&" ")-1)),"/","-"),"年","-"),"月","-"),"日",""))),"") | J3: =IFERROR(MID(I3,FIND("-",I3)+1,99),"")
B4: =IFERROR(IF($B$1=0,"",IF(INDEX(貼り付け!$A$1:$BZ$3001,3,$B$1)="","",IF(ISNUMBER(INDEX(貼り付け!$A$1:$BZ$3001,3,$B$1)),INT(INDEX(貼り付け!$A$1:$BZ$3001,3,$B$1)),DATE(VALUE(LEFT(I4,FIND("-",I4)-1)),VALUE(LEFT(J4,FIND("-",J4)-1)),VALUE(MID(J4,FIND("-",J4)+1,99)))))),"") | C4: =IF($C$1=0,0,IFERROR(VALUE(SUBSTITUTE(SUBSTITUTE(SUBSTITUTE(INDEX(貼り付け!$A$1:$BZ$3001,3,$C$1)&"",",",""),"¥",""),"￥","")),0)) | D4: =IF($D$1=0,0,IFERROR(VALUE(SUBSTITUTE(SUBSTITUTE(SUBSTITUTE(INDEX(貼り付け!$A$1:$BZ$3001,3,$D$1)&"",",",""),"¥",""),"￥","")),0)) | E4: =IF($E$1=0,0,IFERROR(VALUE(SUBSTITUTE(SUBSTITUTE(SUBSTITUTE(INDEX(貼り付け!$A$1:$BZ$3001,3,$E$1)&"",",",""),"¥",""),"￥","")),0)) | F4: =IF($F$1=0,0,IFERROR(VALUE(SUBSTITUTE(SUBSTITUTE(SUBSTITUTE(INDEX(貼り付け!$A$1:$BZ$3001,3,$F$1)&"",",",""),"¥",""),"￥","")),0)) | G4: =IF(ISNUMBER(B4),YEAR(B4),"") | H4: =IF(ISNUMBER(B4),MONTH(B4),"") | I4: =IFERROR(IF($B$1=0,"",IF(ISNUMBER(INDEX(貼り付け!$A$1:$BZ$3001,3,$B$1)),"",SUBSTITUTE(SUBSTITUTE(SUBSTITUTE(SUBSTITUTE(TRIM(LEFT(INDEX(貼り付け!$A$1:$BZ$3001,3,$B$1)&"",FIND(" ",TRIM(INDEX(貼り付け!$A$1:$BZ$3001,3,$B$1)&"")&" ")-1)),"/","-"),"年","-"),"月","-"),"日",""))),"") | J4: =IFERROR(MID(I4,FIND("-",I4)+1,99),"")
B5: =IFERROR(IF($B$1=0,"",IF(INDEX(貼り付け!$A$1:$BZ$3001,4,$B$1)="","",IF(ISNUMBER(INDEX(貼り付け!$A$1:$BZ$3001,4,$B$1)),INT(INDEX(貼り付け!$A$1:$BZ$3001,4,$B$1)),DATE(VALUE(LEFT(I5,FIND("-",I5)-1)),VALUE(LEFT(J5,FIND("-",J5)-1)),VALUE(MID(J5,FIND("-",J5)+1,99)))))),"") | C5: =IF($C$1=0,0,IFERROR(VALUE(SUBSTITUTE(SUBSTITUTE(SUBSTITUTE(INDEX(貼り付け!$A$1:$BZ$3001,4,$C$1)&"",",",""),"¥",""),"￥","")),0)) | D5: =IF($D$1=0,0,IFERROR(VALUE(SUBSTITUTE(SUBSTITUTE(SUBSTITUTE(INDEX(貼り付け!$A$1:$BZ$3001,4,$D$1)&"",",",""),"¥",""),"￥","")),0)) | E5: =IF($E$1=0,0,IFERROR(VALUE(SUBSTITUTE(SUBSTITUTE(SUBSTITUTE(INDEX(貼り付け!$A$1:$BZ$3001,4,$E$1)&"",",",""),"¥",""),"￥","")),0)) | F5: =IF($F$1=0,0,IFERROR(VALUE(SUBSTITUTE(SUBSTITUTE(SUBSTITUTE(INDEX(貼り付け!$A$1:$BZ$3001,4,$F$1)&"",",",""),"¥",""),"￥","")),0)) | G5: =IF(ISNUMBER(B5),YEAR(B5),"") | H5: =IF(ISNUMBER(B5),MONTH(B5),"") | I5: =IFERROR(IF($B$1=0,"",IF(ISNUMBER(INDEX(貼り付け!$A$1:$BZ$3001,4,$B$1)),"",SUBSTITUTE(SUBSTITUTE(SUBSTITUTE(SUBSTITUTE(TRIM(LEFT(INDEX(貼り付け!$A$1:$BZ$3001,4,$B$1)&"",FIND(" ",TRIM(INDEX(貼り付け!$A$1:$BZ$3001,4,$B$1)&"")&" ")-1)),"/","-"),"年","-"),"月","-"),"日",""))),"") | J5: =IFERROR(MID(I5,FIND("-",I5)+1,99),"")
B6: =IFERROR(IF($B$1=0,"",IF(INDEX(貼り付け!$A$1:$BZ$3001,5,$B$1)="","",IF(ISNUMBER(INDEX(貼り付け!$A$1:$BZ$3001,5,$B$1)),INT(INDEX(貼り付け!$A$1:$BZ$3001,5,$B$1)),DATE(VALUE(LEFT(I6,FIND("-",I6)-1)),VALUE(LEFT(J6,FIND("-",J6)-1)),VALUE(MID(J6,FIND("-",J6)+1,99)))))),"") | C6: =IF($C$1=0,0,IFERROR(VALUE(SUBSTITUTE(SUBSTITUTE(SUBSTITUTE(INDEX(貼り付け!$A$1:$BZ$3001,5,$C$1)&"",",",""),"¥",""),"￥","")),0)) | D6: =IF($D$1=0,0,IFERROR(VALUE(SUBSTITUTE(SUBSTITUTE(SUBSTITUTE(INDEX(貼り付け!$A$1:$BZ$3001,5,$D$1)&"",",",""),"¥",""),"￥","")),0)) | E6: =IF($E$1=0,0,IFERROR(VALUE(SUBSTITUTE(SUBSTITUTE(SUBSTITUTE(INDEX(貼り付け!$A$1:$BZ$3001,5,$E$1)&"",",",""),"¥",""),"￥","")),0)) | F6: =IF($F$1=0,0,IFERROR(VALUE(SUBSTITUTE(SUBSTITUTE(SUBSTITUTE(INDEX(貼り付け!$A$1:$BZ$3001,5,$F$1)&"",",",""),"¥",""),"￥","")),0)) | G6: =IF(ISNUMBER(B6),YEAR(B6),"") | H6: =IF(ISNUMBER(B6),MONTH(B6),"") | I6: =IFERROR(IF($B$1=0,"",IF(ISNUMBER(INDEX(貼り付け!$A$1:$BZ$3001,5,$B$1)),"",SUBSTITUTE(SUBSTITUTE(SUBSTITUTE(SUBSTITUTE(TRIM(LEFT(INDEX(貼り付け!$A$1:$BZ$3001,5,$B$1)&"",FIND(" ",TRIM(INDEX(貼り付け!$A$1:$BZ$3001,5,$B$1)&"")&" ")-1)),"/","-"),"年","-"),"月","-"),"日",""))),"") | J6: =IFERROR(MID(I6,FIND("-",I6)+1,99),"")
B7: =IFERROR(IF($B$1=0,"",IF(INDEX(貼り付け!$A$1:$BZ$3001,6,$B$1)="","",IF(ISNUMBER(INDEX(貼り付け!$A$1:$BZ$3001,6,$B$1)),INT(INDEX(貼り付け!$A$1:$BZ$3001,6,$B$1)),DATE(VALUE(LEFT(I7,FIND("-",I7)-1)),VALUE(LEFT(J7,FIND("-",J7)-1)),VALUE(MID(J7,FIND("-",J7)+1,99)))))),"") | C7: =IF($C$1=0,0,IFERROR(VALUE(SUBSTITUTE(SUBSTITUTE(SUBSTITUTE(INDEX(貼り付け!$A$1:$BZ$3001,6,$C$1)&"",",",""),"¥",""),"￥","")),0)) | D7: =IF($D$1=0,0,IFERROR(VALUE(SUBSTITUTE(SUBSTITUTE(SUBSTITUTE(INDEX(貼り付け!$A$1:$BZ$3001,6,$D$1)&"",",",""),"¥",""),"￥","")),0)) | E7: =IF($E$1=0,0,IFERROR(VALUE(SUBSTITUTE(SUBSTITUTE(SUBSTITUTE(INDEX(貼り付け!$A$1:$BZ$3001,6,$E$1)&"",",",""),"¥",""),"￥","")),0)) | F7: =IF($F$1=0,0,IFERROR(VALUE(SUBSTITUTE(SUBSTITUTE(SUBSTITUTE(INDEX(貼り付け!$A$1:$BZ$3001,6,$F$1)&"",",",""),"¥",""),"￥","")),0)) | G7: =IF(ISNUMBER(B7),YEAR(B7),"") | H7: =IF(ISNUMBER(B7),MONTH(B7),"") | I7: =IFERROR(IF($B$1=0,"",IF(ISNUMBER(INDEX(貼り付け!$A$1:$BZ$3001,6,$B$1)),"",SUBSTITUTE(SUBSTITUTE(SUBSTITUTE(SUBSTITUTE(TRIM(LEFT(INDEX(貼り付け!$A$1:$BZ$3001,6,$B$1)&"",FIND(" ",TRIM(INDEX(貼り付け!$A$1:$BZ$3001,6,$B$1)&"")&" ")-1)),"/","-"),"年","-"),"月","-"),"日",""))),"") | J7: =IFERROR(MID(I7,FIND("-",I7)+1,99),"")
B8: =IFERROR(IF($B$1=0,"",IF(INDEX(貼り付け!$A$1:$BZ$3001,7,$B$1)="","",IF(ISNUMBER(INDEX(貼り付け!$A$1:$BZ$3001,7,$B$1)),INT(INDEX(貼り付け!$A$1:$BZ$3001,7,$B$1)),DATE(VALUE(LEFT(I8,FIND("-",I8)-1)),VALUE(LEFT(J8,FIND("-",J8)-1)),VALUE(MID(J8,FIND("-",J8)+1,99)))))),"") | C8: =IF($C$1=0,0,IFERROR(VALUE(SUBSTITUTE(SUBSTITUTE(SUBSTITUTE(INDEX(貼り付け!$A$1:$BZ$3001,7,$C$1)&"",",",""),"¥",""),"￥","")),0)) | D8: =IF($D$1=0,0,IFERROR(VALUE(SUBSTITUTE(SUBSTITUTE(SUBSTITUTE(INDEX(貼り付け!$A$1:$BZ$3001,7,$D$1)&"",",",""),"¥",""),"￥","")),0)) | E8: =IF($E$1=0,0,IFERROR(VALUE(SUBSTITUTE(SUBSTITUTE(SUBSTITUTE(INDEX(貼り付け!$A$1:$BZ$3001,7,$E$1)&"",",",""),"¥",""),"￥","")),0)) | F8: =IF($F$1=0,0,IFERROR(VALUE(SUBSTITUTE(SUBSTITUTE(SUBSTITUTE(INDEX(貼り付け!$A$1:$BZ$3001,7,$F$1)&"",",",""),"¥",""),"￥","")),0)) | G8: =IF(ISNUMBER(B8),YEAR(B8),"") | H8: =IF(ISNUMBER(B8),MONTH(B8),"") | I8: =IFERROR(IF($B$1=0,"",IF(ISNUMBER(INDEX(貼り付け!$A$1:$BZ$3001,7,$B$1)),"",SUBSTITUTE(SUBSTITUTE(SUBSTITUTE(SUBSTITUTE(TRIM(LEFT(INDEX(貼り付け!$A$1:$BZ$3001,7,$B$1)&"",FIND(" ",TRIM(INDEX(貼り付け!$A$1:$BZ$3001,7,$B$1)&"")&" ")-1)),"/","-"),"年","-"),"月","-"),"日",""))),"") | J8: =IFERROR(MID(I8,FIND("-",I8)+1,99),"")
B9: =IFERROR(IF($B$1=0,"",IF(INDEX(貼り付け!$A$1:$BZ$3001,8,$B$1)="","",IF(ISNUMBER(INDEX(貼り付け!$A$1:$BZ$3001,8,$B$1)),INT(INDEX(貼り付け!$A$1:$BZ$3001,8,$B$1)),DATE(VALUE(LEFT(I9,FIND("-",I9)-1)),VALUE(LEFT(J9,FIND("-",J9)-1)),VALUE(MID(J9,FIND("-",J9)+1,99)))))),"") | C9: =IF($C$1=0,0,IFERROR(VALUE(SUBSTITUTE(SUBSTITUTE(SUBSTITUTE(INDEX(貼り付け!$A$1:$BZ$3001,8,$C$1)&"",",",""),"¥",""),"￥","")),0)) | D9: =IF($D$1=0,0,IFERROR(VALUE(SUBSTITUTE(SUBSTITUTE(SUBSTITUTE(INDEX(貼り付け!$A$1:$BZ$3001,8,$D$1)&"",",",""),"¥",""),"￥","")),0)) | E9: =IF($E$1=0,0,IFERROR(VALUE(SUBSTITUTE(SUBSTITUTE(SUBSTITUTE(INDEX(貼り付け!$A$1:$BZ$3001,8,$E$1)&"",",",""),"¥",""),"￥","")),0)) | F9: =IF($F$1=0,0,IFERROR(VALUE(SUBSTITUTE(SUBSTITUTE(SUBSTITUTE(INDEX(貼り付け!$A$1:$BZ$3001,8,$F$1)&"",",",""),"¥",""),"￥","")),0)) | G9: =IF(ISNUMBER(B9),YEAR(B9),"") | H9: =IF(ISNUMBER(B9),MONTH(B9),"") | I9: =IFERROR(IF($B$1=0,"",IF(ISNUMBER(INDEX(貼り付け!$A$1:$BZ$3001,8,$B$1)),"",SUBSTITUTE(SUBSTITUTE(SUBSTITUTE(SUBSTITUTE(TRIM(LEFT(INDEX(貼り付け!$A$1:$BZ$3001,8,$B$1)&"",FIND(" ",TRIM(INDEX(貼り付け!$A$1:$BZ$3001,8,$B$1)&"")&" ")-1)),"/","-"),"年","-"),"月","-"),"日",""))),"") | J9: =IFERROR(MID(I9,FIND("-",I9)+1,99),"")
B10: =IFERROR(IF($B$1=0,"",IF(INDEX(貼り付け!$A$1:$BZ$3001,9,$B$1)="","",IF(ISNUMBER(INDEX(貼り付け!$A$1:$BZ$3001,9,$B$1)),INT(INDEX(貼り付け!$A$1:$BZ$3001,9,$B$1)),DATE(VALUE(LEFT(I10,FIND("-",I10)-1)),VALUE(LEFT(J10,FIND("-",J10)-1)),VALUE(MID(J10,FIND("-",J10)+1,99)))))),"") | C10: =IF($C$1=0,0,IFERROR(VALUE(SUBSTITUTE(SUBSTITUTE(SUBSTITUTE(INDEX(貼り付け!$A$1:$BZ$3001,9,$C$1)&"",",",""),"¥",""),"￥","")),0)) | D10: =IF($D$1=0,0,IFERROR(VALUE(SUBSTITUTE(SUBSTITUTE(SUBSTITUTE(INDEX(貼り付け!$A$1:$BZ$3001,9,$D$1)&"",",",""),"¥",""),"￥","")),0)) | E10: =IF($E$1=0,0,IFERROR(VALUE(SUBSTITUTE(SUBSTITUTE(SUBSTITUTE(INDEX(貼り付け!$A$1:$BZ$3001,9,$E$1)&"",",",""),"¥",""),"￥","")),0)) | F10: =IF($F$1=0,0,IFERROR(VALUE(SUBSTITUTE(SUBSTITUTE(SUBSTITUTE(INDEX(貼り付け!$A$1:$BZ$3001,9,$F$1)&"",",",""),"¥",""),"￥","")),0)) | G10: =IF(ISNUMBER(B10),YEAR(B10),"") | H10: =IF(ISNUMBER(B10),MONTH(B10),"") | I10: =IFERROR(IF($B$1=0,"",IF(ISNUMBER(INDEX(貼り付け!$A$1:$BZ$3001,9,$B$1)),"",SUBSTITUTE(SUBSTITUTE(SUBSTITUTE(SUBSTITUTE(TRIM(LEFT(INDEX(貼り付け!$A$1:$BZ$3001,9,$B$1)&"",FIND(" ",TRIM(INDEX(貼り付け!$A$1:$BZ$3001,9,$B$1)&"")&" ")-1)),"/","-"),"年","-"),"月","-"),"日",""))),"") | J10: =IFERROR(MID(I10,FIND("-",I10)+1,99),"")
B11: =IFERROR(IF($B$1=0,"",IF(INDEX(貼り付け!$A$1:$BZ$3001,10,$B$1)="","",IF(ISNUMBER(INDEX(貼り付け!$A$1:$BZ$3001,10,$B$1)),INT(INDEX(貼り付け!$A$1:$BZ$3001,10,$B$1)),DATE(VALUE(LEFT(I11,FIND("-",I11)-1)),VALUE(LEFT(J11,FIND("-",J11)-1)),VALUE(MID(J11,FIND("-",J11)+1,99)))))),"") | C11: =IF($C$1=0,0,IFERROR(VALUE(SUBSTITUTE(SUBSTITUTE(SUBSTITUTE(INDEX(貼り付け!$A$1:$BZ$3001,10,$C$1)&"",",",""),"¥",""),"￥","")),0)) | D11: =IF($D$1=0,0,IFERROR(VALUE(SUBSTITUTE(SUBSTITUTE(SUBSTITUTE(INDEX(貼り付け!$A$1:$BZ$3001,10,$D$1)&"",",",""),"¥",""),"￥","")),0)) | E11: =IF($E$1=0,0,IFERROR(VALUE(SUBSTITUTE(SUBSTITUTE(SUBSTITUTE(INDEX(貼り付け!$A$1:$BZ$3001,10,$E$1)&"",",",""),"¥",""),"￥","")),0)) | F11: =IF($F$1=0,0,IFERROR(VALUE(SUBSTITUTE(SUBSTITUTE(SUBSTITUTE(INDEX(貼り付け!$A$1:$BZ$3001,10,$F$1)&"",",",""),"¥",""),"￥","")),0)) | G11: =IF(ISNUMBER(B11),YEAR(B11),"") | H11: =IF(ISNUMBER(B11),MONTH(B11),"") | I11: =IFERROR(IF($B$1=0,"",IF(ISNUMBER(INDEX(貼り付け!$A$1:$BZ$3001,10,$B$1)),"",SUBSTITUTE(SUBSTITUTE(SUBSTITUTE(SUBSTITUTE(TRIM(LEFT(INDEX(貼り付け!$A$1:$BZ$3001,10,$B$1)&"",FIND(" ",TRIM(INDEX(貼り付け!$A$1:$BZ$3001,10,$B$1)&"")&" ")-1)),"/","-"),"年","-"),"月","-"),"日",""))),"") | J11: =IFERROR(MID(I11,FIND("-",I11)+1,99),"")
B12: =IFERROR(IF($B$1=0,"",IF(INDEX(貼り付け!$A$1:$BZ$3001,11,$B$1)="","",IF(ISNUMBER(INDEX(貼り付け!$A$1:$BZ$3001,11,$B$1)),INT(INDEX(貼り付け!$A$1:$BZ$3001,11,$B$1)),DATE(VALUE(LEFT(I12,FIND("-",I12)-1)),VALUE(LEFT(J12,FIND("-",J12)-1)),VALUE(MID(J12,FIND("-",J12)+1,99)))))),"") | C12: =IF($C$1=0,0,IFERROR(VALUE(SUBSTITUTE(SUBSTITUTE(SUBSTITUTE(INDEX(貼り付け!$A$1:$BZ$3001,11,$C$1)&"",",",""),"¥",""),"￥","")),0)) | D12: =IF($D$1=0,0,IFERROR(VALUE(SUBSTITUTE(SUBSTITUTE(SUBSTITUTE(INDEX(貼り付け!$A$1:$BZ$3001,11,$D$1)&"",",",""),"¥",""),"￥","")),0)) | E12: =IF($E$1=0,0,IFERROR(VALUE(SUBSTITUTE(SUBSTITUTE(SUBSTITUTE(INDEX(貼り付け!$A$1:$BZ$3001,11,$E$1)&"",",",""),"¥",""),"￥","")),0)) | F12: =IF($F$1=0,0,IFERROR(VALUE(SUBSTITUTE(SUBSTITUTE(SUBSTITUTE(INDEX(貼り付け!$A$1:$BZ$3001,11,$F$1)&"",",",""),"¥",""),"￥","")),0)) | G12: =IF(ISNUMBER(B12),YEAR(B12),"") | H12: =IF(ISNUMBER(B12),MONTH(B12),"") | I12: =IFERROR(IF($B$1=0,"",IF(ISNUMBER(INDEX(貼り付け!$A$1:$BZ$3001,11,$B$1)),"",SUBSTITUTE(SUBSTITUTE(SUBSTITUTE(SUBSTITUTE(TRIM(LEFT(INDEX(貼り付け!$A$1:$BZ$3001,11,$B$1)&"",FIND(" ",TRIM(INDEX(貼り付け!$A$1:$BZ$3001,11,$B$1)&"")&" ")-1)),"/","-"),"年","-"),"月","-"),"日",""))),"") | J12: =IFERROR(MID(I12,FIND("-",I12)+1,99),"")
B13: =IFERROR(IF($B$1=0,"",IF(INDEX(貼り付け!$A$1:$BZ$3001,12,$B$1)="","",IF(ISNUMBER(INDEX(貼り付け!$A$1:$BZ$3001,12,$B$1)),INT(INDEX(貼り付け!$A$1:$BZ$3001,12,$B$1)),DATE(VALUE(LEFT(I13,FIND("-",I13)-1)),VALUE(LEFT(J13,FIND("-",J13)-1)),VALUE(MID(J13,FIND("-",J13)+1,99)))))),"") | C13: =IF($C$1=0,0,IFERROR(VALUE(SUBSTITUTE(SUBSTITUTE(SUBSTITUTE(INDEX(貼り付け!$A$1:$BZ$3001,12,$C$1)&"",",",""),"¥",""),"￥","")),0)) | D13: =IF($D$1=0,0,IFERROR(VALUE(SUBSTITUTE(SUBSTITUTE(SUBSTITUTE(INDEX(貼り付け!$A$1:$BZ$3001,12,$D$1)&"",",",""),"¥",""),"￥","")),0)) | E13: =IF($E$1=0,0,IFERROR(VALUE(SUBSTITUTE(SUBSTITUTE(SUBSTITUTE(INDEX(貼り付け!$A$1:$BZ$3001,12,$E$1)&"",",",""),"¥",""),"￥","")),0)) | F13: =IF($F$1=0,0,IFERROR(VALUE(SUBSTITUTE(SUBSTITUTE(SUBSTITUTE(INDEX(貼り付け!$A$1:$BZ$3001,12,$F$1)&"",",",""),"¥",""),"￥","")),0)) | G13: =IF(ISNUMBER(B13),YEAR(B13),"") | H13: =IF(ISNUMBER(B13),MONTH(B13),"") | I13: =IFERROR(IF($B$1=0,"",IF(ISNUMBER(INDEX(貼り付け!$A$1:$BZ$3001,12,$B$1)),"",SUBSTITUTE(SUBSTITUTE(SUBSTITUTE(SUBSTITUTE(TRIM(LEFT(INDEX(貼り付け!$A$1:$BZ$3001,12,$B$1)&"",FIND(" ",TRIM(INDEX(貼り付け!$A$1:$BZ$3001,12,$B$1)&"")&" ")-1)),"/","-"),"年","-"),"月","-"),"日",""))),"") | J13: =IFERROR(MID(I13,FIND("-",I13)+1,99),"")
B14: =IFERROR(IF($B$1=0,"",IF(INDEX(貼り付け!$A$1:$BZ$3001,13,$B$1)="","",IF(ISNUMBER(INDEX(貼り付け!$A$1:$BZ$3001,13,$B$1)),INT(INDEX(貼り付け!$A$1:$BZ$3001,13,$B$1)),DATE(VALUE(LEFT(I14,FIND("-",I14)-1)),VALUE(LEFT(J14,FIND("-",J14)-1)),VALUE(MID(J14,FIND("-",J14)+1,99)))))),"") | C14: =IF($C$1=0,0,IFERROR(VALUE(SUBSTITUTE(SUBSTITUTE(SUBSTITUTE(INDEX(貼り付け!$A$1:$BZ$3001,13,$C$1)&"",",",""),"¥",""),"￥","")),0)) | D14: =IF($D$1=0,0,IFERROR(VALUE(SUBSTITUTE(SUBSTITUTE(SUBSTITUTE(INDEX(貼り付け!$A$1:$BZ$3001,13,$D$1)&"",",",""),"¥",""),"￥","")),0)) | E14: =IF($E$1=0,0,IFERROR(VALUE(SUBSTITUTE(SUBSTITUTE(SUBSTITUTE(INDEX(貼り付け!$A$1:$BZ$3001,13,$E$1)&"",",",""),"¥",""),"￥","")),0)) | F14: =IF($F$1=0,0,IFERROR(VALUE(SUBSTITUTE(SUBSTITUTE(SUBSTITUTE(INDEX(貼り付け!$A$1:$BZ$3001,13,$F$1)&"",",",""),"¥",""),"￥","")),0)) | G14: =IF(ISNUMBER(B14),YEAR(B14),"") | H14: =IF(ISNUMBER(B14),MONTH(B14),"") | I14: =IFERROR(IF($B$1=0,"",IF(ISNUMBER(INDEX(貼り付け!$A$1:$BZ$3001,13,$B$1)),"",SUBSTITUTE(SUBSTITUTE(SUBSTITUTE(SUBSTITUTE(TRIM(LEFT(INDEX(貼り付け!$A$1:$BZ$3001,13,$B$1)&"",FIND(" ",TRIM(INDEX(貼り付け!$A$1:$BZ$3001,13,$B$1)&"")&" ")-1)),"/","-"),"年","-"),"月","-"),"日",""))),"") | J14: =IFERROR(MID(I14,FIND("-",I14)+1,99),"")
B15: =IFERROR(IF($B$1=0,"",IF(INDEX(貼り付け!$A$1:$BZ$3001,14,$B$1)="","",IF(ISNUMBER(INDEX(貼り付け!$A$1:$BZ$3001,14,$B$1)),INT(INDEX(貼り付け!$A$1:$BZ$3001,14,$B$1)),DATE(VALUE(LEFT(I15,FIND("-",I15)-1)),VALUE(LEFT(J15,FIND("-",J15)-1)),VALUE(MID(J15,FIND("-",J15)+1,99)))))),"") | C15: =IF($C$1=0,0,IFERROR(VALUE(SUBSTITUTE(SUBSTITUTE(SUBSTITUTE(INDEX(貼り付け!$A$1:$BZ$3001,14,$C$1)&"",",",""),"¥",""),"￥","")),0)) | D15: =IF($D$1=0,0,IFERROR(VALUE(SUBSTITUTE(SUBSTITUTE(SUBSTITUTE(INDEX(貼り付け!$A$1:$BZ$3001,14,$D$1)&"",",",""),"¥",""),"￥","")),0)) | E15: =IF($E$1=0,0,IFERROR(VALUE(SUBSTITUTE(SUBSTITUTE(SUBSTITUTE(INDEX(貼り付け!$A$1:$BZ$3001,14,$E$1)&"",",",""),"¥",""),"￥","")),0)) | F15: =IF($F$1=0,0,IFERROR(VALUE(SUBSTITUTE(SUBSTITUTE(SUBSTITUTE(INDEX(貼り付け!$A$1:$BZ$3001,14,$F$1)&"",",",""),"¥",""),"￥","")),0)) | G15: =IF(ISNUMBER(B15),YEAR(B15),"") | H15: =IF(ISNUMBER(B15),MONTH(B15),"") | I15: =IFERROR(IF($B$1=0,"",IF(ISNUMBER(INDEX(貼り付け!$A$1:$BZ$3001,14,$B$1)),"",SUBSTITUTE(SUBSTITUTE(SUBSTITUTE(SUBSTITUTE(TRIM(LEFT(INDEX(貼り付け!$A$1:$BZ$3001,14,$B$1)&"",FIND(" ",TRIM(INDEX(貼り付け!$A$1:$BZ$3001,14,$B$1)&"")&" ")-1)),"/","-"),"年","-"),"月","-"),"日",""))),"") | J15: =IFERROR(MID(I15,FIND("-",I15)+1,99),"")
B16: =IFERROR(IF($B$1=0,"",IF(INDEX(貼り付け!$A$1:$BZ$3001,15,$B$1)="","",IF(ISNUMBER(INDEX(貼り付け!$A$1:$BZ$3001,15,$B$1)),INT(INDEX(貼り付け!$A$1:$BZ$3001,15,$B$1)),DATE(VALUE(LEFT(I16,FIND("-",I16)-1)),VALUE(LEFT(J16,FIND("-",J16)-1)),VALUE(MID(J16,FIND("-",J16)+1,99)))))),"") | C16: =IF($C$1=0,0,IFERROR(VALUE(SUBSTITUTE(SUBSTITUTE(SUBSTITUTE(INDEX(貼り付け!$A$1:$BZ$3001,15,$C$1)&"",",",""),"¥",""),"￥","")),0)) | D16: =IF($D$1=0,0,IFERROR(VALUE(SUBSTITUTE(SUBSTITUTE(SUBSTITUTE(INDEX(貼り付け!$A$1:$BZ$3001,15,$D$1)&"",",",""),"¥",""),"￥","")),0)) | E16: =IF($E$1=0,0,IFERROR(VALUE(SUBSTITUTE(SUBSTITUTE(SUBSTITUTE(INDEX(貼り付け!$A$1:$BZ$3001,15,$E$1)&"",",",""),"¥",""),"￥","")),0)) | F16: =IF($F$1=0,0,IFERROR(VALUE(SUBSTITUTE(SUBSTITUTE(SUBSTITUTE(INDEX(貼り付け!$A$1:$BZ$3001,15,$F$1)&"",",",""),"¥",""),"￥","")),0)) | G16: =IF(ISNUMBER(B16),YEAR(B16),"") | H16: =IF(ISNUMBER(B16),MONTH(B16),"") | I16: =IFERROR(IF($B$1=0,"",IF(ISNUMBER(INDEX(貼り付け!$A$1:$BZ$3001,15,$B$1)),"",SUBSTITUTE(SUBSTITUTE(SUBSTITUTE(SUBSTITUTE(TRIM(LEFT(INDEX(貼り付け!$A$1:$BZ$3001,15,$B$1)&"",FIND(" ",TRIM(INDEX(貼り付け!$A$1:$BZ$3001,15,$B$1)&"")&" ")-1)),"/","-"),"年","-"),"月","-"),"日",""))),"") | J16: =IFERROR(MID(I16,FIND("-",I16)+1,99),"")
B17: =IFERROR(IF($B$1=0,"",IF(INDEX(貼り付け!$A$1:$BZ$3001,16,$B$1)="","",IF(ISNUMBER(INDEX(貼り付け!$A$1:$BZ$3001,16,$B$1)),INT(INDEX(貼り付け!$A$1:$BZ$3001,16,$B$1)),DATE(VALUE(LEFT(I17,FIND("-",I17)-1)),VALUE(LEFT(J17,FIND("-",J17)-1)),VALUE(MID(J17,FIND("-",J17)+1,99)))))),"") | C17: =IF($C$1=0,0,IFERROR(VALUE(SUBSTITUTE(SUBSTITUTE(SUBSTITUTE(INDEX(貼り付け!$A$1:$BZ$3001,16,$C$1)&"",",",""),"¥",""),"￥","")),0)) | D17: =IF($D$1=0,0,IFERROR(VALUE(SUBSTITUTE(SUBSTITUTE(SUBSTITUTE(INDEX(貼り付け!$A$1:$BZ$3001,16,$D$1)&"",",",""),"¥",""),"￥","")),0)) | E17: =IF($E$1=0,0,IFERROR(VALUE(SUBSTITUTE(SUBSTITUTE(SUBSTITUTE(INDEX(貼り付け!$A$1:$BZ$3001,16,$E$1)&"",",",""),"¥",""),"￥","")),0)) | F17: =IF($F$1=0,0,IFERROR(VALUE(SUBSTITUTE(SUBSTITUTE(SUBSTITUTE(INDEX(貼り付け!$A$1:$BZ$3001,16,$F$1)&"",",",""),"¥",""),"￥","")),0)) | G17: =IF(ISNUMBER(B17),YEAR(B17),"") | H17: =IF(ISNUMBER(B17),MONTH(B17),"") | I17: =IFERROR(IF($B$1=0,"",IF(ISNUMBER(INDEX(貼り付け!$A$1:$BZ$3001,16,$B$1)),"",SUBSTITUTE(SUBSTITUTE(SUBSTITUTE(SUBSTITUTE(TRIM(LEFT(INDEX(貼り付け!$A$1:$BZ$3001,16,$B$1)&"",FIND(" ",TRIM(INDEX(貼り付け!$A$1:$BZ$3001,16,$B$1)&"")&" ")-1)),"/","-"),"年","-"),"月","-"),"日",""))),"") | J17: =IFERROR(MID(I17,FIND("-",I17)+1,99),"")
B18: =IFERROR(IF($B$1=0,"",IF(INDEX(貼り付け!$A$1:$BZ$3001,17,$B$1)="","",IF(ISNUMBER(INDEX(貼り付け!$A$1:$BZ$3001,17,$B$1)),INT(INDEX(貼り付け!$A$1:$BZ$3001,17,$B$1)),DATE(VALUE(LEFT(I18,FIND("-",I18)-1)),VALUE(LEFT(J18,FIND("-",J18)-1)),VALUE(MID(J18,FIND("-",J18)+1,99)))))),"") | C18: =IF($C$1=0,0,IFERROR(VALUE(SUBSTITUTE(SUBSTITUTE(SUBSTITUTE(INDEX(貼り付け!$A$1:$BZ$3001,17,$C$1)&"",",",""),"¥",""),"￥","")),0)) | D18: =IF($D$1=0,0,IFERROR(VALUE(SUBSTITUTE(SUBSTITUTE(SUBSTITUTE(INDEX(貼り付け!$A$1:$BZ$3001,17,$D$1)&"",",",""),"¥",""),"￥","")),0)) | E18: =IF($E$1=0,0,IFERROR(VALUE(SUBSTITUTE(SUBSTITUTE(SUBSTITUTE(INDEX(貼り付け!$A$1:$BZ$3001,17,$E$1)&"",",",""),"¥",""),"￥","")),0)) | F18: =IF($F$1=0,0,IFERROR(VALUE(SUBSTITUTE(SUBSTITUTE(SUBSTITUTE(INDEX(貼り付け!$A$1:$BZ$3001,17,$F$1)&"",",",""),"¥",""),"￥","")),0)) | G18: =IF(ISNUMBER(B18),YEAR(B18),"") | H18: =IF(ISNUMBER(B18),MONTH(B18),"") | I18: =IFERROR(IF($B$1=0,"",IF(ISNUMBER(INDEX(貼り付け!$A$1:$BZ$3001,17,$B$1)),"",SUBSTITUTE(SUBSTITUTE(SUBSTITUTE(SUBSTITUTE(TRIM(LEFT(INDEX(貼り付け!$A$1:$BZ$3001,17,$B$1)&"",FIND(" ",TRIM(INDEX(貼り付け!$A$1:$BZ$3001,17,$B$1)&"")&" ")-1)),"/","-"),"年","-"),"月","-"),"日",""))),"") | J18: =IFERROR(MID(I18,FIND("-",I18)+1,99),"")
B19: =IFERROR(IF($B$1=0,"",IF(INDEX(貼り付け!$A$1:$BZ$3001,18,$B$1)="","",IF(ISNUMBER(INDEX(貼り付け!$A$1:$BZ$3001,18,$B$1)),INT(INDEX(貼り付け!$A$1:$BZ$3001,18,$B$1)),DATE(VALUE(LEFT(I19,FIND("-",I19)-1)),VALUE(LEFT(J19,FIND("-",J19)-1)),VALUE(MID(J19,FIND("-",J19)+1,99)))))),"") | C19: =IF($C$1=0,0,IFERROR(VALUE(SUBSTITUTE(SUBSTITUTE(SUBSTITUTE(INDEX(貼り付け!$A$1:$BZ$3001,18,$C$1)&"",",",""),"¥",""),"￥","")),0)) | D19: =IF($D$1=0,0,IFERROR(VALUE(SUBSTITUTE(SUBSTITUTE(SUBSTITUTE(INDEX(貼り付け!$A$1:$BZ$3001,18,$D$1)&"",",",""),"¥",""),"￥","")),0)) | E19: =IF($E$1=0,0,IFERROR(VALUE(SUBSTITUTE(SUBSTITUTE(SUBSTITUTE(INDEX(貼り付け!$A$1:$BZ$3001,18,$E$1)&"",",",""),"¥",""),"￥","")),0)) | F19: =IF($F$1=0,0,IFERROR(VALUE(SUBSTITUTE(SUBSTITUTE(SUBSTITUTE(INDEX(貼り付け!$A$1:$BZ$3001,18,$F$1)&"",",",""),"¥",""),"￥","")),0)) | G19: =IF(ISNUMBER(B19),YEAR(B19),"") | H19: =IF(ISNUMBER(B19),MONTH(B19),"") | I19: =IFERROR(IF($B$1=0,"",IF(ISNUMBER(INDEX(貼り付け!$A$1:$BZ$3001,18,$B$1)),"",SUBSTITUTE(SUBSTITUTE(SUBSTITUTE(SUBSTITUTE(TRIM(LEFT(INDEX(貼り付け!$A$1:$BZ$3001,18,$B$1)&"",FIND(" ",TRIM(INDEX(貼り付け!$A$1:$BZ$3001,18,$B$1)&"")&" ")-1)),"/","-"),"年","-"),"月","-"),"日",""))),"") | J19: =IFERROR(MID(I19,FIND("-",I19)+1,99),"")
B20: =IFERROR(IF($B$1=0,"",IF(INDEX(貼り付け!$A$1:$BZ$3001,19,$B$1)="","",IF(ISNUMBER(INDEX(貼り付け!$A$1:$BZ$3001,19,$B$1)),INT(INDEX(貼り付け!$A$1:$BZ$3001,19,$B$1)),DATE(VALUE(LEFT(I20,FIND("-",I20)-1)),VALUE(LEFT(J20,FIND("-",J20)-1)),VALUE(MID(J20,FIND("-",J20)+1,99)))))),"") | C20: =IF($C$1=0,0,IFERROR(VALUE(SUBSTITUTE(SUBSTITUTE(SUBSTITUTE(INDEX(貼り付け!$A$1:$BZ$3001,19,$C$1)&"",",",""),"¥",""),"￥","")),0)) | D20: =IF($D$1=0,0,IFERROR(VALUE(SUBSTITUTE(SUBSTITUTE(SUBSTITUTE(INDEX(貼り付け!$A$1:$BZ$3001,19,$D$1)&"",",",""),"¥",""),"￥","")),0)) | E20: =IF($E$1=0,0,IFERROR(VALUE(SUBSTITUTE(SUBSTITUTE(SUBSTITUTE(INDEX(貼り付け!$A$1:$BZ$3001,19,$E$1)&"",",",""),"¥",""),"￥","")),0)) | F20: =IF($F$1=0,0,IFERROR(VALUE(SUBSTITUTE(SUBSTITUTE(SUBSTITUTE(INDEX(貼り付け!$A$1:$BZ$3001,19,$F$1)&"",",",""),"¥",""),"￥","")),0)) | G20: =IF(ISNUMBER(B20),YEAR(B20),"") | H20: =IF(ISNUMBER(B20),MONTH(B20),"") | I20: =IFERROR(IF($B$1=0,"",IF(ISNUMBER(INDEX(貼り付け!$A$1:$BZ$3001,19,$B$1)),"",SUBSTITUTE(SUBSTITUTE(SUBSTITUTE(SUBSTITUTE(TRIM(LEFT(INDEX(貼り付け!$A$1:$BZ$3001,19,$B$1)&"",FIND(" ",TRIM(INDEX(貼り付け!$A$1:$BZ$3001,19,$B$1)&"")&" ")-1)),"/","-"),"年","-"),"月","-"),"日",""))),"") | J20: =IFERROR(MID(I20,FIND("-",I20)+1,99),"")
B21: =IFERROR(IF($B$1=0,"",IF(INDEX(貼り付け!$A$1:$BZ$3001,20,$B$1)="","",IF(ISNUMBER(INDEX(貼り付け!$A$1:$BZ$3001,20,$B$1)),INT(INDEX(貼り付け!$A$1:$BZ$3001,20,$B$1)),DATE(VALUE(LEFT(I21,FIND("-",I21)-1)),VALUE(LEFT(J21,FIND("-",J21)-1)),VALUE(MID(J21,FIND("-",J21)+1,99)))))),"") | C21: =IF($C$1=0,0,IFERROR(VALUE(SUBSTITUTE(SUBSTITUTE(SUBSTITUTE(INDEX(貼り付け!$A$1:$BZ$3001,20,$C$1)&"",",",""),"¥",""),"￥","")),0)) | D21: =IF($D$1=0,0,IFERROR(VALUE(SUBSTITUTE(SUBSTITUTE(SUBSTITUTE(INDEX(貼り付け!$A$1:$BZ$3001,20,$D$1)&"",",",""),"¥",""),"￥","")),0)) | E21: =IF($E$1=0,0,IFERROR(VALUE(SUBSTITUTE(SUBSTITUTE(SUBSTITUTE(INDEX(貼り付け!$A$1:$BZ$3001,20,$E$1)&"",",",""),"¥",""),"￥","")),0)) | F21: =IF($F$1=0,0,IFERROR(VALUE(SUBSTITUTE(SUBSTITUTE(SUBSTITUTE(INDEX(貼り付け!$A$1:$BZ$3001,20,$F$1)&"",",",""),"¥",""),"￥","")),0)) | G21: =IF(ISNUMBER(B21),YEAR(B21),"") | H21: =IF(ISNUMBER(B21),MONTH(B21),"") | I21: =IFERROR(IF($B$1=0,"",IF(ISNUMBER(INDEX(貼り付け!$A$1:$BZ$3001,20,$B$1)),"",SUBSTITUTE(SUBSTITUTE(SUBSTITUTE(SUBSTITUTE(TRIM(LEFT(INDEX(貼り付け!$A$1:$BZ$3001,20,$B$1)&"",FIND(" ",TRIM(INDEX(貼り付け!$A$1:$BZ$3001,20,$B$1)&"")&" ")-1)),"/","-"),"年","-"),"月","-"),"日",""))),"") | J21: =IFERROR(MID(I21,FIND("-",I21)+1,99),"")
B22: =IFERROR(IF($B$1=0,"",IF(INDEX(貼り付け!$A$1:$BZ$3001,21,$B$1)="","",IF(ISNUMBER(INDEX(貼り付け!$A$1:$BZ$3001,21,$B$1)),INT(INDEX(貼り付け!$A$1:$BZ$3001,21,$B$1)),DATE(VALUE(LEFT(I22,FIND("-",I22)-1)),VALUE(LEFT(J22,FIND("-",J22)-1)),VALUE(MID(J22,FIND("-",J22)+1,99)))))),"") | C22: =IF($C$1=0,0,IFERROR(VALUE(SUBSTITUTE(SUBSTITUTE(SUBSTITUTE(INDEX(貼り付け!$A$1:$BZ$3001,21,$C$1)&"",",",""),"¥",""),"￥","")),0)) | D22: =IF($D$1=0,0,IFERROR(VALUE(SUBSTITUTE(SUBSTITUTE(SUBSTITUTE(INDEX(貼り付け!$A$1:$BZ$3001,21,$D$1)&"",",",""),"¥",""),"￥","")),0)) | E22: =IF($E$1=0,0,IFERROR(VALUE(SUBSTITUTE(SUBSTITUTE(SUBSTITUTE(INDEX(貼り付け!$A$1:$BZ$3001,21,$E$1)&"",",",""),"¥",""),"￥","")),0)) | F22: =IF($F$1=0,0,IFERROR(VALUE(SUBSTITUTE(SUBSTITUTE(SUBSTITUTE(INDEX(貼り付け!$A$1:$BZ$3001,21,$F$1)&"",",",""),"¥",""),"￥","")),0)) | G22: =IF(ISNUMBER(B22),YEAR(B22),"") | H22: =IF(ISNUMBER(B22),MONTH(B22),"") | I22: =IFERROR(IF($B$1=0,"",IF(ISNUMBER(INDEX(貼り付け!$A$1:$BZ$3001,21,$B$1)),"",SUBSTITUTE(SUBSTITUTE(SUBSTITUTE(SUBSTITUTE(TRIM(LEFT(INDEX(貼り付け!$A$1:$BZ$3001,21,$B$1)&"",FIND(" ",TRIM(INDEX(貼り付け!$A$1:$BZ$3001,21,$B$1)&"")&" ")-1)),"/","-"),"年","-"),"月","-"),"日",""))),"") | J22: =IFERROR(MID(I22,FIND("-",I22)+1,99),"")
B23: =IFERROR(IF($B$1=0,"",IF(INDEX(貼り付け!$A$1:$BZ$3001,22,$B$1)="","",IF(ISNUMBER(INDEX(貼り付け!$A$1:$BZ$3001,22,$B$1)),INT(INDEX(貼り付け!$A$1:$BZ$3001,22,$B$1)),DATE(VALUE(LEFT(I23,FIND("-",I23)-1)),VALUE(LEFT(J23,FIND("-",J23)-1)),VALUE(MID(J23,FIND("-",J23)+1,99)))))),"") | C23: =IF($C$1=0,0,IFERROR(VALUE(SUBSTITUTE(SUBSTITUTE(SUBSTITUTE(INDEX(貼り付け!$A$1:$BZ$3001,22,$C$1)&"",",",""),"¥",""),"￥","")),0)) | D23: =IF($D$1=0,0,IFERROR(VALUE(SUBSTITUTE(SUBSTITUTE(SUBSTITUTE(INDEX(貼り付け!$A$1:$BZ$3001,22,$D$1)&"",",",""),"¥",""),"￥","")),0)) | E23: =IF($E$1=0,0,IFERROR(VALUE(SUBSTITUTE(SUBSTITUTE(SUBSTITUTE(INDEX(貼り付け!$A$1:$BZ$3001,22,$E$1)&"",",",""),"¥",""),"￥","")),0)) | F23: =IF($F$1=0,0,IFERROR(VALUE(SUBSTITUTE(SUBSTITUTE(SUBSTITUTE(INDEX(貼り付け!$A$1:$BZ$3001,22,$F$1)&"",",",""),"¥",""),"￥","")),0)) | G23: =IF(ISNUMBER(B23),YEAR(B23),"") | H23: =IF(ISNUMBER(B23),MONTH(B23),"") | I23: =IFERROR(IF($B$1=0,"",IF(ISNUMBER(INDEX(貼り付け!$A$1:$BZ$3001,22,$B$1)),"",SUBSTITUTE(SUBSTITUTE(SUBSTITUTE(SUBSTITUTE(TRIM(LEFT(INDEX(貼り付け!$A$1:$BZ$3001,22,$B$1)&"",FIND(" ",TRIM(INDEX(貼り付け!$A$1:$BZ$3001,22,$B$1)&"")&" ")-1)),"/","-"),"年","-"),"月","-"),"日",""))),"") | J23: =IFERROR(MID(I23,FIND("-",I23)+1,99),"")
B24: =IFERROR(IF($B$1=0,"",IF(INDEX(貼り付け!$A$1:$BZ$3001,23,$B$1)="","",IF(ISNUMBER(INDEX(貼り付け!$A$1:$BZ$3001,23,$B$1)),INT(INDEX(貼り付け!$A$1:$BZ$3001,23,$B$1)),DATE(VALUE(LEFT(I24,FIND("-",I24)-1)),VALUE(LEFT(J24,FIND("-",J24)-1)),VALUE(MID(J24,FIND("-",J24)+1,99)))))),"") | C24: =IF($C$1=0,0,IFERROR(VALUE(SUBSTITUTE(SUBSTITUTE(SUBSTITUTE(INDEX(貼り付け!$A$1:$BZ$3001,23,$C$1)&"",",",""),"¥",""),"￥","")),0)) | D24: =IF($D$1=0,0,IFERROR(VALUE(SUBSTITUTE(SUBSTITUTE(SUBSTITUTE(INDEX(貼り付け!$A$1:$BZ$3001,23,$D$1)&"",",",""),"¥",""),"￥","")),0)) | E24: =IF($E$1=0,0,IFERROR(VALUE(SUBSTITUTE(SUBSTITUTE(SUBSTITUTE(INDEX(貼り付け!$A$1:$BZ$3001,23,$E$1)&"",",",""),"¥",""),"￥","")),0)) | F24: =IF($F$1=0,0,IFERROR(VALUE(SUBSTITUTE(SUBSTITUTE(SUBSTITUTE(INDEX(貼り付け!$A$1:$BZ$3001,23,$F$1)&"",",",""),"¥",""),"￥","")),0)) | G24: =IF(ISNUMBER(B24),YEAR(B24),"") | H24: =IF(ISNUMBER(B24),MONTH(B24),"") | I24: =IFERROR(IF($B$1=0,"",IF(ISNUMBER(INDEX(貼り付け!$A$1:$BZ$3001,23,$B$1)),"",SUBSTITUTE(SUBSTITUTE(SUBSTITUTE(SUBSTITUTE(TRIM(LEFT(INDEX(貼り付け!$A$1:$BZ$3001,23,$B$1)&"",FIND(" ",TRIM(INDEX(貼り付け!$A$1:$BZ$3001,23,$B$1)&"")&" ")-1)),"/","-"),"年","-"),"月","-"),"日",""))),"") | J24: =IFERROR(MID(I24,FIND("-",I24)+1,99),"")
B25: =IFERROR(IF($B$1=0,"",IF(INDEX(貼り付け!$A$1:$BZ$3001,24,$B$1)="","",IF(ISNUMBER(INDEX(貼り付け!$A$1:$BZ$3001,24,$B$1)),INT(INDEX(貼り付け!$A$1:$BZ$3001,24,$B$1)),DATE(VALUE(LEFT(I25,FIND("-",I25)-1)),VALUE(LEFT(J25,FIND("-",J25)-1)),VALUE(MID(J25,FIND("-",J25)+1,99)))))),"") | C25: =IF($C$1=0,0,IFERROR(VALUE(SUBSTITUTE(SUBSTITUTE(SUBSTITUTE(INDEX(貼り付け!$A$1:$BZ$3001,24,$C$1)&"",",",""),"¥",""),"￥","")),0)) | D25: =IF($D$1=0,0,IFERROR(VALUE(SUBSTITUTE(SUBSTITUTE(SUBSTITUTE(INDEX(貼り付け!$A$1:$BZ$3001,24,$D$1)&"",",",""),"¥",""),"￥","")),0)) | E25: =IF($E$1=0,0,IFERROR(VALUE(SUBSTITUTE(SUBSTITUTE(SUBSTITUTE(INDEX(貼り付け!$A$1:$BZ$3001,24,$E$1)&"",",",""),"¥",""),"￥","")),0)) | F25: =IF($F$1=0,0,IFERROR(VALUE(SUBSTITUTE(SUBSTITUTE(SUBSTITUTE(INDEX(貼り付け!$A$1:$BZ$3001,24,$F$1)&"",",",""),"¥",""),"￥","")),0)) | G25: =IF(ISNUMBER(B25),YEAR(B25),"") | H25: =IF(ISNUMBER(B25),MONTH(B25),"") | I25: =IFERROR(IF($B$1=0,"",IF(ISNUMBER(INDEX(貼り付け!$A$1:$BZ$3001,24,$B$1)),"",SUBSTITUTE(SUBSTITUTE(SUBSTITUTE(SUBSTITUTE(TRIM(LEFT(INDEX(貼り付け!$A$1:$BZ$3001,24,$B$1)&"",FIND(" ",TRIM(INDEX(貼り付け!$A$1:$BZ$3001,24,$B$1)&"")&" ")-1)),"/","-"),"年","-"),"月","-"),"日",""))),"") | J25: =IFERROR(MID(I25,FIND("-",I25)+1,99),"")
B26: =IFERROR(IF($B$1=0,"",IF(INDEX(貼り付け!$A$1:$BZ$3001,25,$B$1)="","",IF(ISNUMBER(INDEX(貼り付け!$A$1:$BZ$3001,25,$B$1)),INT(INDEX(貼り付け!$A$1:$BZ$3001,25,$B$1)),DATE(VALUE(LEFT(I26,FIND("-",I26)-1)),VALUE(LEFT(J26,FIND("-",J26)-1)),VALUE(MID(J26,FIND("-",J26)+1,99)))))),"") | C26: =IF($C$1=0,0,IFERROR(VALUE(SUBSTITUTE(SUBSTITUTE(SUBSTITUTE(INDEX(貼り付け!$A$1:$BZ$3001,25,$C$1)&"",",",""),"¥",""),"￥","")),0)) | D26: =IF($D$1=0,0,IFERROR(VALUE(SUBSTITUTE(SUBSTITUTE(SUBSTITUTE(INDEX(貼り付け!$A$1:$BZ$3001,25,$D$1)&"",",",""),"¥",""),"￥","")),0)) | E26: =IF($E$1=0,0,IFERROR(VALUE(SUBSTITUTE(SUBSTITUTE(SUBSTITUTE(INDEX(貼り付け!$A$1:$BZ$3001,25,$E$1)&"",",",""),"¥",""),"￥","")),0)) | F26: =IF($F$1=0,0,IFERROR(VALUE(SUBSTITUTE(SUBSTITUTE(SUBSTITUTE(INDEX(貼り付け!$A$1:$BZ$3001,25,$F$1)&"",",",""),"¥",""),"￥","")),0)) | G26: =IF(ISNUMBER(B26),YEAR(B26),"") | H26: =IF(ISNUMBER(B26),MONTH(B26),"") | I26: =IFERROR(IF($B$1=0,"",IF(ISNUMBER(INDEX(貼り付け!$A$1:$BZ$3001,25,$B$1)),"",SUBSTITUTE(SUBSTITUTE(SUBSTITUTE(SUBSTITUTE(TRIM(LEFT(INDEX(貼り付け!$A$1:$BZ$3001,25,$B$1)&"",FIND(" ",TRIM(INDEX(貼り付け!$A$1:$BZ$3001,25,$B$1)&"")&" ")-1)),"/","-"),"年","-"),"月","-"),"日",""))),"") | J26: =IFERROR(MID(I26,FIND("-",I26)+1,99),"")
B27: =IFERROR(IF($B$1=0,"",IF(INDEX(貼り付け!$A$1:$BZ$3001,26,$B$1)="","",IF(ISNUMBER(INDEX(貼り付け!$A$1:$BZ$3001,26,$B$1)),INT(INDEX(貼り付け!$A$1:$BZ$3001,26,$B$1)),DATE(VALUE(LEFT(I27,FIND("-",I27)-1)),VALUE(LEFT(J27,FIND("-",J27)-1)),VALUE(MID(J27,FIND("-",J27)+1,99)))))),"") | C27: =IF($C$1=0,0,IFERROR(VALUE(SUBSTITUTE(SUBSTITUTE(SUBSTITUTE(INDEX(貼り付け!$A$1:$BZ$3001,26,$C$1)&"",",",""),"¥",""),"￥","")),0)) | D27: =IF($D$1=0,0,IFERROR(VALUE(SUBSTITUTE(SUBSTITUTE(SUBSTITUTE(INDEX(貼り付け!$A$1:$BZ$3001,26,$D$1)&"",",",""),"¥",""),"￥","")),0)) | E27: =IF($E$1=0,0,IFERROR(VALUE(SUBSTITUTE(SUBSTITUTE(SUBSTITUTE(INDEX(貼り付け!$A$1:$BZ$3001,26,$E$1)&"",",",""),"¥",""),"￥","")),0)) | F27: =IF($F$1=0,0,IFERROR(VALUE(SUBSTITUTE(SUBSTITUTE(SUBSTITUTE(INDEX(貼り付け!$A$1:$BZ$3001,26,$F$1)&"",",",""),"¥",""),"￥","")),0)) | G27: =IF(ISNUMBER(B27),YEAR(B27),"") | H27: =IF(ISNUMBER(B27),MONTH(B27),"") | I27: =IFERROR(IF($B$1=0,"",IF(ISNUMBER(INDEX(貼り付け!$A$1:$BZ$3001,26,$B$1)),"",SUBSTITUTE(SUBSTITUTE(SUBSTITUTE(SUBSTITUTE(TRIM(LEFT(INDEX(貼り付け!$A$1:$BZ$3001,26,$B$1)&"",FIND(" ",TRIM(INDEX(貼り付け!$A$1:$BZ$3001,26,$B$1)&"")&" ")-1)),"/","-"),"年","-"),"月","-"),"日",""))),"") | J27: =IFERROR(MID(I27,FIND("-",I27)+1,99),"")
B28: =IFERROR(IF($B$1=0,"",IF(INDEX(貼り付け!$A$1:$BZ$3001,27,$B$1)="","",IF(ISNUMBER(INDEX(貼り付け!$A$1:$BZ$3001,27,$B$1)),INT(INDEX(貼り付け!$A$1:$BZ$3001,27,$B$1)),DATE(VALUE(LEFT(I28,FIND("-",I28)-1)),VALUE(LEFT(J28,FIND("-",J28)-1)),VALUE(MID(J28,FIND("-",J28)+1,99)))))),"") | C28: =IF($C$1=0,0,IFERROR(VALUE(SUBSTITUTE(SUBSTITUTE(SUBSTITUTE(INDEX(貼り付け!$A$1:$BZ$3001,27,$C$1)&"",",",""),"¥",""),"￥","")),0)) | D28: =IF($D$1=0,0,IFERROR(VALUE(SUBSTITUTE(SUBSTITUTE(SUBSTITUTE(INDEX(貼り付け!$A$1:$BZ$3001,27,$D$1)&"",",",""),"¥",""),"￥","")),0)) | E28: =IF($E$1=0,0,IFERROR(VALUE(SUBSTITUTE(SUBSTITUTE(SUBSTITUTE(INDEX(貼り付け!$A$1:$BZ$3001,27,$E$1)&"",",",""),"¥",""),"￥","")),0)) | F28: =IF($F$1=0,0,IFERROR(VALUE(SUBSTITUTE(SUBSTITUTE(SUBSTITUTE(INDEX(貼り付け!$A$1:$BZ$3001,27,$F$1)&"",",",""),"¥",""),"￥","")),0)) | G28: =IF(ISNUMBER(B28),YEAR(B28),"") | H28: =IF(ISNUMBER(B28),MONTH(B28),"") | I28: =IFERROR(IF($B$1=0,"",IF(ISNUMBER(INDEX(貼り付け!$A$1:$BZ$3001,27,$B$1)),"",SUBSTITUTE(SUBSTITUTE(SUBSTITUTE(SUBSTITUTE(TRIM(LEFT(INDEX(貼り付け!$A$1:$BZ$3001,27,$B$1)&"",FIND(" ",TRIM(INDEX(貼り付け!$A$1:$BZ$3001,27,$B$1)&"")&" ")-1)),"/","-"),"年","-"),"月","-"),"日",""))),"") | J28: =IFERROR(MID(I28,FIND("-",I28)+1,99),"")
B29: =IFERROR(IF($B$1=0,"",IF(INDEX(貼り付け!$A$1:$BZ$3001,28,$B$1)="","",IF(ISNUMBER(INDEX(貼り付け!$A$1:$BZ$3001,28,$B$1)),INT(INDEX(貼り付け!$A$1:$BZ$3001,28,$B$1)),DATE(VALUE(LEFT(I29,FIND("-",I29)-1)),VALUE(LEFT(J29,FIND("-",J29)-1)),VALUE(MID(J29,FIND("-",J29)+1,99)))))),"") | C29: =IF($C$1=0,0,IFERROR(VALUE(SUBSTITUTE(SUBSTITUTE(SUBSTITUTE(INDEX(貼り付け!$A$1:$BZ$3001,28,$C$1)&"",",",""),"¥",""),"￥","")),0)) | D29: =IF($D$1=0,0,IFERROR(VALUE(SUBSTITUTE(SUBSTITUTE(SUBSTITUTE(INDEX(貼り付け!$A$1:$BZ$3001,28,$D$1)&"",",",""),"¥",""),"￥","")),0)) | E29: =IF($E$1=0,0,IFERROR(VALUE(SUBSTITUTE(SUBSTITUTE(SUBSTITUTE(INDEX(貼り付け!$A$1:$BZ$3001,28,$E$1)&"",",",""),"¥",""),"￥","")),0)) | F29: =IF($F$1=0,0,IFERROR(VALUE(SUBSTITUTE(SUBSTITUTE(SUBSTITUTE(INDEX(貼り付け!$A$1:$BZ$3001,28,$F$1)&"",",",""),"¥",""),"￥","")),0)) | G29: =IF(ISNUMBER(B29),YEAR(B29),"") | H29: =IF(ISNUMBER(B29),MONTH(B29),"") | I29: =IFERROR(IF($B$1=0,"",IF(ISNUMBER(INDEX(貼り付け!$A$1:$BZ$3001,28,$B$1)),"",SUBSTITUTE(SUBSTITUTE(SUBSTITUTE(SUBSTITUTE(TRIM(LEFT(INDEX(貼り付け!$A$1:$BZ$3001,28,$B$1)&"",FIND(" ",TRIM(INDEX(貼り付け!$A$1:$BZ$3001,28,$B$1)&"")&" ")-1)),"/","-"),"年","-"),"月","-"),"日",""))),"") | J29: =IFERROR(MID(I29,FIND("-",I29)+1,99),"")
B30: =IFERROR(IF($B$1=0,"",IF(INDEX(貼り付け!$A$1:$BZ$3001,29,$B$1)="","",IF(ISNUMBER(INDEX(貼り付け!$A$1:$BZ$3001,29,$B$1)),INT(INDEX(貼り付け!$A$1:$BZ$3001,29,$B$1)),DATE(VALUE(LEFT(I30,FIND("-",I30)-1)),VALUE(LEFT(J30,FIND("-",J30)-1)),VALUE(MID(J30,FIND("-",J30)+1,99)))))),"") | C30: =IF($C$1=0,0,IFERROR(VALUE(SUBSTITUTE(SUBSTITUTE(SUBSTITUTE(INDEX(貼り付け!$A$1:$BZ$3001,29,$C$1)&"",",",""),"¥",""),"￥","")),0)) | D30: =IF($D$1=0,0,IFERROR(VALUE(SUBSTITUTE(SUBSTITUTE(SUBSTITUTE(INDEX(貼り付け!$A$1:$BZ$3001,29,$D$1)&"",",",""),"¥",""),"￥","")),0)) | E30: =IF($E$1=0,0,IFERROR(VALUE(SUBSTITUTE(SUBSTITUTE(SUBSTITUTE(INDEX(貼り付け!$A$1:$BZ$3001,29,$E$1)&"",",",""),"¥",""),"￥","")),0)) | F30: =IF($F$1=0,0,IFERROR(VALUE(SUBSTITUTE(SUBSTITUTE(SUBSTITUTE(INDEX(貼り付け!$A$1:$BZ$3001,29,$F$1)&"",",",""),"¥",""),"￥","")),0)) | G30: =IF(ISNUMBER(B30),YEAR(B30),"") | H30: =IF(ISNUMBER(B30),MONTH(B30),"") | I30: =IFERROR(IF($B$1=0,"",IF(ISNUMBER(INDEX(貼り付け!$A$1:$BZ$3001,29,$B$1)),"",SUBSTITUTE(SUBSTITUTE(SUBSTITUTE(SUBSTITUTE(TRIM(LEFT(INDEX(貼り付け!$A$1:$BZ$3001,29,$B$1)&"",FIND(" ",TRIM(INDEX(貼り付け!$A$1:$BZ$3001,29,$B$1)&"")&" ")-1)),"/","-"),"年","-"),"月","-"),"日",""))),"") | J30: =IFERROR(MID(I30,FIND("-",I30)+1,99),"")
B31: =IFERROR(IF($B$1=0,"",IF(INDEX(貼り付け!$A$1:$BZ$3001,30,$B$1)="","",IF(ISNUMBER(INDEX(貼り付け!$A$1:$BZ$3001,30,$B$1)),INT(INDEX(貼り付け!$A$1:$BZ$3001,30,$B$1)),DATE(VALUE(LEFT(I31,FIND("-",I31)-1)),VALUE(LEFT(J31,FIND("-",J31)-1)),VALUE(MID(J31,FIND("-",J31)+1,99)))))),"") | C31: =IF($C$1=0,0,IFERROR(VALUE(SUBSTITUTE(SUBSTITUTE(SUBSTITUTE(INDEX(貼り付け!$A$1:$BZ$3001,30,$C$1)&"",",",""),"¥",""),"￥","")),0)) | D31: =IF($D$1=0,0,IFERROR(VALUE(SUBSTITUTE(SUBSTITUTE(SUBSTITUTE(INDEX(貼り付け!$A$1:$BZ$3001,30,$D$1)&"",",",""),"¥",""),"￥","")),0)) | E31: =IF($E$1=0,0,IFERROR(VALUE(SUBSTITUTE(SUBSTITUTE(SUBSTITUTE(INDEX(貼り付け!$A$1:$BZ$3001,30,$E$1)&"",",",""),"¥",""),"￥","")),0)) | F31: =IF($F$1=0,0,IFERROR(VALUE(SUBSTITUTE(SUBSTITUTE(SUBSTITUTE(INDEX(貼り付け!$A$1:$BZ$3001,30,$F$1)&"",",",""),"¥",""),"￥","")),0)) | G31: =IF(ISNUMBER(B31),YEAR(B31),"") | H31: =IF(ISNUMBER(B31),MONTH(B31),"") | I31: =IFERROR(IF($B$1=0,"",IF(ISNUMBER(INDEX(貼り付け!$A$1:$BZ$3001,30,$B$1)),"",SUBSTITUTE(SUBSTITUTE(SUBSTITUTE(SUBSTITUTE(TRIM(LEFT(INDEX(貼り付け!$A$1:$BZ$3001,30,$B$1)&"",FIND(" ",TRIM(INDEX(貼り付け!$A$1:$BZ$3001,30,$B$1)&"")&" ")-1)),"/","-"),"年","-"),"月","-"),"日",""))),"") | J31: =IFERROR(MID(I31,FIND("-",I31)+1,99),"")
B32: =IFERROR(IF($B$1=0,"",IF(INDEX(貼り付け!$A$1:$BZ$3001,31,$B$1)="","",IF(ISNUMBER(INDEX(貼り付け!$A$1:$BZ$3001,31,$B$1)),INT(INDEX(貼り付け!$A$1:$BZ$3001,31,$B$1)),DATE(VALUE(LEFT(I32,FIND("-",I32)-1)),VALUE(LEFT(J32,FIND("-",J32)-1)),VALUE(MID(J32,FIND("-",J32)+1,99)))))),"") | C32: =IF($C$1=0,0,IFERROR(VALUE(SUBSTITUTE(SUBSTITUTE(SUBSTITUTE(INDEX(貼り付け!$A$1:$BZ$3001,31,$C$1)&"",",",""),"¥",""),"￥","")),0)) | D32: =IF($D$1=0,0,IFERROR(VALUE(SUBSTITUTE(SUBSTITUTE(SUBSTITUTE(INDEX(貼り付け!$A$1:$BZ$3001,31,$D$1)&"",",",""),"¥",""),"￥","")),0)) | E32: =IF($E$1=0,0,IFERROR(VALUE(SUBSTITUTE(SUBSTITUTE(SUBSTITUTE(INDEX(貼り付け!$A$1:$BZ$3001,31,$E$1)&"",",",""),"¥",""),"￥","")),0)) | F32: =IF($F$1=0,0,IFERROR(VALUE(SUBSTITUTE(SUBSTITUTE(SUBSTITUTE(INDEX(貼り付け!$A$1:$BZ$3001,31,$F$1)&"",",",""),"¥",""),"￥","")),0)) | G32: =IF(ISNUMBER(B32),YEAR(B32),"") | H32: =IF(ISNUMBER(B32),MONTH(B32),"") | I32: =IFERROR(IF($B$1=0,"",IF(ISNUMBER(INDEX(貼り付け!$A$1:$BZ$3001,31,$B$1)),"",SUBSTITUTE(SUBSTITUTE(SUBSTITUTE(SUBSTITUTE(TRIM(LEFT(INDEX(貼り付け!$A$1:$BZ$3001,31,$B$1)&"",FIND(" ",TRIM(INDEX(貼り付け!$A$1:$BZ$3001,31,$B$1)&"")&" ")-1)),"/","-"),"年","-"),"月","-"),"日",""))),"") | J32: =IFERROR(MID(I32,FIND("-",I32)+1,99),"")
B33: =IFERROR(IF($B$1=0,"",IF(INDEX(貼り付け!$A$1:$BZ$3001,32,$B$1)="","",IF(ISNUMBER(INDEX(貼り付け!$A$1:$BZ$3001,32,$B$1)),INT(INDEX(貼り付け!$A$1:$BZ$3001,32,$B$1)),DATE(VALUE(LEFT(I33,FIND("-",I33)-1)),VALUE(LEFT(J33,FIND("-",J33)-1)),VALUE(MID(J33,FIND("-",J33)+1,99)))))),"") | C33: =IF($C$1=0,0,IFERROR(VALUE(SUBSTITUTE(SUBSTITUTE(SUBSTITUTE(INDEX(貼り付け!$A$1:$BZ$3001,32,$C$1)&"",",",""),"¥",""),"￥","")),0)) | D33: =IF($D$1=0,0,IFERROR(VALUE(SUBSTITUTE(SUBSTITUTE(SUBSTITUTE(INDEX(貼り付け!$A$1:$BZ$3001,32,$D$1)&"",",",""),"¥",""),"￥","")),0)) | E33: =IF($E$1=0,0,IFERROR(VALUE(SUBSTITUTE(SUBSTITUTE(SUBSTITUTE(INDEX(貼り付け!$A$1:$BZ$3001,32,$E$1)&"",",",""),"¥",""),"￥","")),0)) | F33: =IF($F$1=0,0,IFERROR(VALUE(SUBSTITUTE(SUBSTITUTE(SUBSTITUTE(INDEX(貼り付け!$A$1:$BZ$3001,32,$F$1)&"",",",""),"¥",""),"￥","")),0)) | G33: =IF(ISNUMBER(B33),YEAR(B33),"") | H33: =IF(ISNUMBER(B33),MONTH(B33),"") | I33: =IFERROR(IF($B$1=0,"",IF(ISNUMBER(INDEX(貼り付け!$A$1:$BZ$3001,32,$B$1)),"",SUBSTITUTE(SUBSTITUTE(SUBSTITUTE(SUBSTITUTE(TRIM(LEFT(INDEX(貼り付け!$A$1:$BZ$3001,32,$B$1)&"",FIND(" ",TRIM(INDEX(貼り付け!$A$1:$BZ$3001,32,$B$1)&"")&" ")-1)),"/","-"),"年","-"),"月","-"),"日",""))),"") | J33: =IFERROR(MID(I33,FIND("-",I33)+1,99),"")
B34: =IFERROR(IF($B$1=0,"",IF(INDEX(貼り付け!$A$1:$BZ$3001,33,$B$1)="","",IF(ISNUMBER(INDEX(貼り付け!$A$1:$BZ$3001,33,$B$1)),INT(INDEX(貼り付け!$A$1:$BZ$3001,33,$B$1)),DATE(VALUE(LEFT(I34,FIND("-",I34)-1)),VALUE(LEFT(J34,FIND("-",J34)-1)),VALUE(MID(J34,FIND("-",J34)+1,99)))))),"") | C34: =IF($C$1=0,0,IFERROR(VALUE(SUBSTITUTE(SUBSTITUTE(SUBSTITUTE(INDEX(貼り付け!$A$1:$BZ$3001,33,$C$1)&"",",",""),"¥",""),"￥","")),0)) | D34: =IF($D$1=0,0,IFERROR(VALUE(SUBSTITUTE(SUBSTITUTE(SUBSTITUTE(INDEX(貼り付け!$A$1:$BZ$3001,33,$D$1)&"",",",""),"¥",""),"￥","")),0)) | E34: =IF($E$1=0,0,IFERROR(VALUE(SUBSTITUTE(SUBSTITUTE(SUBSTITUTE(INDEX(貼り付け!$A$1:$BZ$3001,33,$E$1)&"",",",""),"¥",""),"￥","")),0)) | F34: =IF($F$1=0,0,IFERROR(VALUE(SUBSTITUTE(SUBSTITUTE(SUBSTITUTE(INDEX(貼り付け!$A$1:$BZ$3001,33,$F$1)&"",",",""),"¥",""),"￥","")),0)) | G34: =IF(ISNUMBER(B34),YEAR(B34),"") | H34: =IF(ISNUMBER(B34),MONTH(B34),"") | I34: =IFERROR(IF($B$1=0,"",IF(ISNUMBER(INDEX(貼り付け!$A$1:$BZ$3001,33,$B$1)),"",SUBSTITUTE(SUBSTITUTE(SUBSTITUTE(SUBSTITUTE(TRIM(LEFT(INDEX(貼り付け!$A$1:$BZ$3001,33,$B$1)&"",FIND(" ",TRIM(INDEX(貼り付け!$A$1:$BZ$3001,33,$B$1)&"")&" ")-1)),"/","-"),"年","-"),"月","-"),"日",""))),"") | J34: =IFERROR(MID(I34,FIND("-",I34)+1,99),"")
B35: =IFERROR(IF($B$1=0,"",IF(INDEX(貼り付け!$A$1:$BZ$3001,34,$B$1)="","",IF(ISNUMBER(INDEX(貼り付け!$A$1:$BZ$3001,34,$B$1)),INT(INDEX(貼り付け!$A$1:$BZ$3001,34,$B$1)),DATE(VALUE(LEFT(I35,FIND("-",I35)-1)),VALUE(LEFT(J35,FIND("-",J35)-1)),VALUE(MID(J35,FIND("-",J35)+1,99)))))),"") | C35: =IF($C$1=0,0,IFERROR(VALUE(SUBSTITUTE(SUBSTITUTE(SUBSTITUTE(INDEX(貼り付け!$A$1:$BZ$3001,34,$C$1)&"",",",""),"¥",""),"￥","")),0)) | D35: =IF($D$1=0,0,IFERROR(VALUE(SUBSTITUTE(SUBSTITUTE(SUBSTITUTE(INDEX(貼り付け!$A$1:$BZ$3001,34,$D$1)&"",",",""),"¥",""),"￥","")),0)) | E35: =IF($E$1=0,0,IFERROR(VALUE(SUBSTITUTE(SUBSTITUTE(SUBSTITUTE(INDEX(貼り付け!$A$1:$BZ$3001,34,$E$1)&"",",",""),"¥",""),"￥","")),0)) | F35: =IF($F$1=0,0,IFERROR(VALUE(SUBSTITUTE(SUBSTITUTE(SUBSTITUTE(INDEX(貼り付け!$A$1:$BZ$3001,34,$F$1)&"",",",""),"¥",""),"￥","")),0)) | G35: =IF(ISNUMBER(B35),YEAR(B35),"") | H35: =IF(ISNUMBER(B35),MONTH(B35),"") | I35: =IFERROR(IF($B$1=0,"",IF(ISNUMBER(INDEX(貼り付け!$A$1:$BZ$3001,34,$B$1)),"",SUBSTITUTE(SUBSTITUTE(SUBSTITUTE(SUBSTITUTE(TRIM(LEFT(INDEX(貼り付け!$A$1:$BZ$3001,34,$B$1)&"",FIND(" ",TRIM(INDEX(貼り付け!$A$1:$BZ$3001,34,$B$1)&"")&" ")-1)),"/","-"),"年","-"),"月","-"),"日",""))),"") | J35: =IFERROR(MID(I35,FIND("-",I35)+1,99),"")
B36: =IFERROR(IF($B$1=0,"",IF(INDEX(貼り付け!$A$1:$BZ$3001,35,$B$1)="","",IF(ISNUMBER(INDEX(貼り付け!$A$1:$BZ$3001,35,$B$1)),INT(INDEX(貼り付け!$A$1:$BZ$3001,35,$B$1)),DATE(VALUE(LEFT(I36,FIND("-",I36)-1)),VALUE(LEFT(J36,FIND("-",J36)-1)),VALUE(MID(J36,FIND("-",J36)+1,99)))))),"") | C36: =IF($C$1=0,0,IFERROR(VALUE(SUBSTITUTE(SUBSTITUTE(SUBSTITUTE(INDEX(貼り付け!$A$1:$BZ$3001,35,$C$1)&"",",",""),"¥",""),"￥","")),0)) | D36: =IF($D$1=0,0,IFERROR(VALUE(SUBSTITUTE(SUBSTITUTE(SUBSTITUTE(INDEX(貼り付け!$A$1:$BZ$3001,35,$D$1)&"",",",""),"¥",""),"￥","")),0)) | E36: =IF($E$1=0,0,IFERROR(VALUE(SUBSTITUTE(SUBSTITUTE(SUBSTITUTE(INDEX(貼り付け!$A$1:$BZ$3001,35,$E$1)&"",",",""),"¥",""),"￥","")),0)) | F36: =IF($F$1=0,0,IFERROR(VALUE(SUBSTITUTE(SUBSTITUTE(SUBSTITUTE(INDEX(貼り付け!$A$1:$BZ$3001,35,$F$1)&"",",",""),"¥",""),"￥","")),0)) | G36: =IF(ISNUMBER(B36),YEAR(B36),"") | H36: =IF(ISNUMBER(B36),MONTH(B36),"") | I36: =IFERROR(IF($B$1=0,"",IF(ISNUMBER(INDEX(貼り付け!$A$1:$BZ$3001,35,$B$1)),"",SUBSTITUTE(SUBSTITUTE(SUBSTITUTE(SUBSTITUTE(TRIM(LEFT(INDEX(貼り付け!$A$1:$BZ$3001,35,$B$1)&"",FIND(" ",TRIM(INDEX(貼り付け!$A$1:$BZ$3001,35,$B$1)&"")&" ")-1)),"/","-"),"年","-"),"月","-"),"日",""))),"") | J36: =IFERROR(MID(I36,FIND("-",I36)+1,99),"")
B37: =IFERROR(IF($B$1=0,"",IF(INDEX(貼り付け!$A$1:$BZ$3001,36,$B$1)="","",IF(ISNUMBER(INDEX(貼り付け!$A$1:$BZ$3001,36,$B$1)),INT(INDEX(貼り付け!$A$1:$BZ$3001,36,$B$1)),DATE(VALUE(LEFT(I37,FIND("-",I37)-1)),VALUE(LEFT(J37,FIND("-",J37)-1)),VALUE(MID(J37,FIND("-",J37)+1,99)))))),"") | C37: =IF($C$1=0,0,IFERROR(VALUE(SUBSTITUTE(SUBSTITUTE(SUBSTITUTE(INDEX(貼り付け!$A$1:$BZ$3001,36,$C$1)&"",",",""),"¥",""),"￥","")),0)) | D37: =IF($D$1=0,0,IFERROR(VALUE(SUBSTITUTE(SUBSTITUTE(SUBSTITUTE(INDEX(貼り付け!$A$1:$BZ$3001,36,$D$1)&"",",",""),"¥",""),"￥","")),0)) | E37: =IF($E$1=0,0,IFERROR(VALUE(SUBSTITUTE(SUBSTITUTE(SUBSTITUTE(INDEX(貼り付け!$A$1:$BZ$3001,36,$E$1)&"",",",""),"¥",""),"￥","")),0)) | F37: =IF($F$1=0,0,IFERROR(VALUE(SUBSTITUTE(SUBSTITUTE(SUBSTITUTE(INDEX(貼り付け!$A$1:$BZ$3001,36,$F$1)&"",",",""),"¥",""),"￥","")),0)) | G37: =IF(ISNUMBER(B37),YEAR(B37),"") | H37: =IF(ISNUMBER(B37),MONTH(B37),"") | I37: =IFERROR(IF($B$1=0,"",IF(ISNUMBER(INDEX(貼り付け!$A$1:$BZ$3001,36,$B$1)),"",SUBSTITUTE(SUBSTITUTE(SUBSTITUTE(SUBSTITUTE(TRIM(LEFT(INDEX(貼り付け!$A$1:$BZ$3001,36,$B$1)&"",FIND(" ",TRIM(INDEX(貼り付け!$A$1:$BZ$3001,36,$B$1)&"")&" ")-1)),"/","-"),"年","-"),"月","-"),"日",""))),"") | J37: =IFERROR(MID(I37,FIND("-",I37)+1,99),"")
B38: =IFERROR(IF($B$1=0,"",IF(INDEX(貼り付け!$A$1:$BZ$3001,37,$B$1)="","",IF(ISNUMBER(INDEX(貼り付け!$A$1:$BZ$3001,37,$B$1)),INT(INDEX(貼り付け!$A$1:$BZ$3001,37,$B$1)),DATE(VALUE(LEFT(I38,FIND("-",I38)-1)),VALUE(LEFT(J38,FIND("-",J38)-1)),VALUE(MID(J38,FIND("-",J38)+1,99)))))),"") | C38: =IF($C$1=0,0,IFERROR(VALUE(SUBSTITUTE(SUBSTITUTE(SUBSTITUTE(INDEX(貼り付け!$A$1:$BZ$3001,37,$C$1)&"",",",""),"¥",""),"￥","")),0)) | D38: =IF($D$1=0,0,IFERROR(VALUE(SUBSTITUTE(SUBSTITUTE(SUBSTITUTE(INDEX(貼り付け!$A$1:$BZ$3001,37,$D$1)&"",",",""),"¥",""),"￥","")),0)) | E38: =IF($E$1=0,0,IFERROR(VALUE(SUBSTITUTE(SUBSTITUTE(SUBSTITUTE(INDEX(貼り付け!$A$1:$BZ$3001,37,$E$1)&"",",",""),"¥",""),"￥","")),0)) | F38: =IF($F$1=0,0,IFERROR(VALUE(SUBSTITUTE(SUBSTITUTE(SUBSTITUTE(INDEX(貼り付け!$A$1:$BZ$3001,37,$F$1)&"",",",""),"¥",""),"￥","")),0)) | G38: =IF(ISNUMBER(B38),YEAR(B38),"") | H38: =IF(ISNUMBER(B38),MONTH(B38),"") | I38: =IFERROR(IF($B$1=0,"",IF(ISNUMBER(INDEX(貼り付け!$A$1:$BZ$3001,37,$B$1)),"",SUBSTITUTE(SUBSTITUTE(SUBSTITUTE(SUBSTITUTE(TRIM(LEFT(INDEX(貼り付け!$A$1:$BZ$3001,37,$B$1)&"",FIND(" ",TRIM(INDEX(貼り付け!$A$1:$BZ$3001,37,$B$1)&"")&" ")-1)),"/","-"),"年","-"),"月","-"),"日",""))),"") | J38: =IFERROR(MID(I38,FIND("-",I38)+1,99),"")
B39: =IFERROR(IF($B$1=0,"",IF(INDEX(貼り付け!$A$1:$BZ$3001,38,$B$1)="","",IF(ISNUMBER(INDEX(貼り付け!$A$1:$BZ$3001,38,$B$1)),INT(INDEX(貼り付け!$A$1:$BZ$3001,38,$B$1)),DATE(VALUE(LEFT(I39,FIND("-",I39)-1)),VALUE(LEFT(J39,FIND("-",J39)-1)),VALUE(MID(J39,FIND("-",J39)+1,99)))))),"") | C39: =IF($C$1=0,0,IFERROR(VALUE(SUBSTITUTE(SUBSTITUTE(SUBSTITUTE(INDEX(貼り付け!$A$1:$BZ$3001,38,$C$1)&"",",",""),"¥",""),"￥","")),0)) | D39: =IF($D$1=0,0,IFERROR(VALUE(SUBSTITUTE(SUBSTITUTE(SUBSTITUTE(INDEX(貼り付け!$A$1:$BZ$3001,38,$D$1)&"",",",""),"¥",""),"￥","")),0)) | E39: =IF($E$1=0,0,IFERROR(VALUE(SUBSTITUTE(SUBSTITUTE(SUBSTITUTE(INDEX(貼り付け!$A$1:$BZ$3001,38,$E$1)&"",",",""),"¥",""),"￥","")),0)) | F39: =IF($F$1=0,0,IFERROR(VALUE(SUBSTITUTE(SUBSTITUTE(SUBSTITUTE(INDEX(貼り付け!$A$1:$BZ$3001,38,$F$1)&"",",",""),"¥",""),"￥","")),0)) | G39: =IF(ISNUMBER(B39),YEAR(B39),"") | H39: =IF(ISNUMBER(B39),MONTH(B39),"") | I39: =IFERROR(IF($B$1=0,"",IF(ISNUMBER(INDEX(貼り付け!$A$1:$BZ$3001,38,$B$1)),"",SUBSTITUTE(SUBSTITUTE(SUBSTITUTE(SUBSTITUTE(TRIM(LEFT(INDEX(貼り付け!$A$1:$BZ$3001,38,$B$1)&"",FIND(" ",TRIM(INDEX(貼り付け!$A$1:$BZ$3001,38,$B$1)&"")&" ")-1)),"/","-"),"年","-"),"月","-"),"日",""))),"") | J39: =IFERROR(MID(I39,FIND("-",I39)+1,99),"")
B40: =IFERROR(IF($B$1=0,"",IF(INDEX(貼り付け!$A$1:$BZ$3001,39,$B$1)="","",IF(ISNUMBER(INDEX(貼り付け!$A$1:$BZ$3001,39,$B$1)),INT(INDEX(貼り付け!$A$1:$BZ$3001,39,$B$1)),DATE(VALUE(LEFT(I40,FIND("-",I40)-1)),VALUE(LEFT(J40,FIND("-",J40)-1)),VALUE(MID(J40,FIND("-",J40)+1,99)))))),"") | C40: =IF($C$1=0,0,IFERROR(VALUE(SUBSTITUTE(SUBSTITUTE(SUBSTITUTE(INDEX(貼り付け!$A$1:$BZ$3001,39,$C$1)&"",",",""),"¥",""),"￥","")),0)) | D40: =IF($D$1=0,0,IFERROR(VALUE(SUBSTITUTE(SUBSTITUTE(SUBSTITUTE(INDEX(貼り付け!$A$1:$BZ$3001,39,$D$1)&"",",",""),"¥",""),"￥","")),0)) | E40: =IF($E$1=0,0,IFERROR(VALUE(SUBSTITUTE(SUBSTITUTE(SUBSTITUTE(INDEX(貼り付け!$A$1:$BZ$3001,39,$E$1)&"",",",""),"¥",""),"￥","")),0)) | F40: =IF($F$1=0,0,IFERROR(VALUE(SUBSTITUTE(SUBSTITUTE(SUBSTITUTE(INDEX(貼り付け!$A$1:$BZ$3001,39,$F$1)&"",",",""),"¥",""),"￥","")),0)) | G40: =IF(ISNUMBER(B40),YEAR(B40),"") | H40: =IF(ISNUMBER(B40),MONTH(B40),"") | I40: =IFERROR(IF($B$1=0,"",IF(ISNUMBER(INDEX(貼り付け!$A$1:$BZ$3001,39,$B$1)),"",SUBSTITUTE(SUBSTITUTE(SUBSTITUTE(SUBSTITUTE(TRIM(LEFT(INDEX(貼り付け!$A$1:$BZ$3001,39,$B$1)&"",FIND(" ",TRIM(INDEX(貼り付け!$A$1:$BZ$3001,39,$B$1)&"")&" ")-1)),"/","-"),"年","-"),"月","-"),"日",""))),"") | J40: =IFERROR(MID(I40,FIND("-",I40)+1,99),"")
...
